2020-01-02 09:56:52,392 [8] ERROR Microsoft.AspNetCore.Server.Kestrel - Connection id "0HLSF4RV5CEE3", Request id "0HLSF4RV5CEE3:00000003": An unhandled exception was thrown by the application.
System.InvalidOperationException: StatusCode cannot be set because the response has already started.
   at Microsoft.AspNetCore.Server.Kestrel.Core.Internal.Http.Frame.ThrowResponseAlreadyStartedException(String value)
   at Microsoft.AspNetCore.Server.Kestrel.Core.Internal.Http.Frame.set_StatusCode(Int32 value)
   at Microsoft.AspNetCore.Server.Kestrel.Core.Internal.Http.Frame.Microsoft.AspNetCore.Http.Features.IHttpResponseFeature.set_StatusCode(Int32 value)
   at Hangfire.Dashboard.AspNetCoreDashboardMiddleware.<Invoke>d__5.MoveNext()
--- End of stack trace from previous location where exception was thrown ---
   at System.Runtime.ExceptionServices.ExceptionDispatchInfo.Throw()
   at System.Runtime.CompilerServices.TaskAwaiter.HandleNonSuccessAndDebuggerNotification(Task task)
   at Microsoft.AspNetCore.Builder.Extensions.MapMiddleware.<Invoke>d__3.MoveNext()
--- End of stack trace from previous location where exception was thrown ---
   at System.Runtime.ExceptionServices.ExceptionDispatchInfo.Throw()
   at System.Runtime.CompilerServices.TaskAwaiter.HandleNonSuccessAndDebuggerNotification(Task task)
   at Microsoft.AspNetCore.Hosting.Internal.RequestServicesContainerMiddleware.<Invoke>d__3.MoveNext()
--- End of stack trace from previous location where exception was thrown ---
   at System.Runtime.ExceptionServices.ExceptionDispatchInfo.Throw()
   at System.Runtime.CompilerServices.TaskAwaiter.HandleNonSuccessAndDebuggerNotification(Task task)
   at Microsoft.AspNetCore.Server.Kestrel.Core.Internal.Http.Frame`1.<ProcessRequestsAsync>d__2.MoveNext()
2020-01-02 09:56:59,095 [7] ERROR Microsoft.AspNetCore.Server.Kestrel - Connection id "0HLSF4RV5CEE4", Request id "0HLSF4RV5CEE4:00000001": An unhandled exception was thrown by the application.
System.InvalidOperationException: StatusCode cannot be set because the response has already started.
   at Microsoft.AspNetCore.Server.Kestrel.Core.Internal.Http.Frame.ThrowResponseAlreadyStartedException(String value)
   at Microsoft.AspNetCore.Server.Kestrel.Core.Internal.Http.Frame.set_StatusCode(Int32 value)
   at Microsoft.AspNetCore.Server.Kestrel.Core.Internal.Http.Frame.Microsoft.AspNetCore.Http.Features.IHttpResponseFeature.set_StatusCode(Int32 value)
   at Hangfire.Dashboard.AspNetCoreDashboardMiddleware.<Invoke>d__5.MoveNext()
--- End of stack trace from previous location where exception was thrown ---
   at System.Runtime.ExceptionServices.ExceptionDispatchInfo.Throw()
   at System.Runtime.CompilerServices.TaskAwaiter.HandleNonSuccessAndDebuggerNotification(Task task)
   at Microsoft.AspNetCore.Builder.Extensions.MapMiddleware.<Invoke>d__3.MoveNext()
--- End of stack trace from previous location where exception was thrown ---
   at System.Runtime.ExceptionServices.ExceptionDispatchInfo.Throw()
   at System.Runtime.CompilerServices.TaskAwaiter.HandleNonSuccessAndDebuggerNotification(Task task)
   at Microsoft.AspNetCore.Hosting.Internal.RequestServicesContainerMiddleware.<Invoke>d__3.MoveNext()
--- End of stack trace from previous location where exception was thrown ---
   at System.Runtime.ExceptionServices.ExceptionDispatchInfo.Throw()
   at System.Runtime.CompilerServices.TaskAwaiter.HandleNonSuccessAndDebuggerNotification(Task task)
   at Microsoft.AspNetCore.Server.Kestrel.Core.Internal.Http.Frame`1.<ProcessRequestsAsync>d__2.MoveNext()
2020-01-02 09:57:55,675 [8] ERROR Microsoft.AspNetCore.Server.Kestrel - Connection id "0HLSF4RV5CEE7", Request id "0HLSF4RV5CEE7:00000001": An unhandled exception was thrown by the application.
System.AggregateException: One or more errors occurred. (Current user did not login to the application!) ---> Abp.Authorization.AbpAuthorizationException: Current user did not login to the application!
   at Abp.Authorization.AuthorizationHelper.<AuthorizeAsync>d__15.MoveNext() in C:\work\Test\FrameDemo\ABP\Abp\Authorization\AuthorizationHelper.cs:line 47
--- End of stack trace from previous location where exception was thrown ---
   at System.Runtime.ExceptionServices.ExceptionDispatchInfo.Throw()
   at System.Runtime.CompilerServices.TaskAwaiter.HandleNonSuccessAndDebuggerNotification(Task task)
   at Abp.Authorization.AuthorizationHelper.<CheckPermissions>d__18.MoveNext() in C:\work\Test\FrameDemo\ABP\Abp\Authorization\AuthorizationHelper.cs:line 107
--- End of stack trace from previous location where exception was thrown ---
   at System.Runtime.ExceptionServices.ExceptionDispatchInfo.Throw()
   at System.Runtime.CompilerServices.TaskAwaiter.HandleNonSuccessAndDebuggerNotification(Task task)
   at Abp.Authorization.AuthorizationHelper.<AuthorizeAsync>d__16.MoveNext() in C:\work\Test\FrameDemo\ABP\Abp\Authorization\AuthorizationHelper.cs:line 56
--- End of stack trace from previous location where exception was thrown ---
   at System.Runtime.ExceptionServices.ExceptionDispatchInfo.Throw()
   at System.Runtime.CompilerServices.TaskAwaiter.HandleNonSuccessAndDebuggerNotification(Task task)
   at Nito.AsyncEx.Synchronous.TaskExtensions.WaitAndUnwrapException(Task task)
   at System.Threading.ExecutionContext.Run(ExecutionContext executionContext, ContextCallback callback, Object state)
   at System.Threading.Tasks.Task.ExecuteWithThreadLocal(Task& currentTaskSlot)
--- End of stack trace from previous location where exception was thrown ---
   at System.Runtime.ExceptionServices.ExceptionDispatchInfo.Throw()
   at System.Runtime.CompilerServices.TaskAwaiter.HandleNonSuccessAndDebuggerNotification(Task task)
   at Nito.AsyncEx.Synchronous.TaskExtensions.WaitAndUnwrapException(Task task)
   at Nito.AsyncEx.AsyncContext.Run(Func`1 action)
   at Abp.Threading.AsyncHelper.RunSync(Func`1 action) in C:\work\Test\FrameDemo\ABP\Abp\Threading\AsyncHelper.cs:line 52
   at Abp.Authorization.AuthorizationHelperExtensions.Authorize(IAuthorizationHelper authorizationHelper, MethodInfo methodInfo, Type type) in C:\work\Test\FrameDemo\ABP\Abp\Authorization\AuthorizationHelperExtensions.cs:line 28
   at Abp.Authorization.AuthorizationInterceptor.Intercept(IInvocation invocation) in C:\work\Test\FrameDemo\ABP\Abp\Authorization\AuthorizationInterceptor.cs:line 19
   at Castle.DynamicProxy.AbstractInvocation.Proceed()
   at Abp.Domain.Uow.UnitOfWorkInterceptor.PerformAsyncUow(IInvocation invocation, UnitOfWorkOptions options) in C:\work\Test\FrameDemo\ABP\Abp\Domain\Uow\UnitOfWorkInterceptor.cs:line 83
   at Abp.Domain.Uow.UnitOfWorkInterceptor.PerformUow(IInvocation invocation, UnitOfWorkOptions options) in C:\work\Test\FrameDemo\ABP\Abp\Domain\Uow\UnitOfWorkInterceptor.cs:line 55
   at Abp.Domain.Uow.UnitOfWorkInterceptor.Intercept(IInvocation invocation) in C:\work\Test\FrameDemo\ABP\Abp\Domain\Uow\UnitOfWorkInterceptor.cs:line 48
   at Castle.DynamicProxy.AbstractInvocation.Proceed()
   at Abp.Auditing.AuditingInterceptor.Intercept(IInvocation invocation) in C:\work\Test\FrameDemo\ABP\Abp\Auditing\AuditingInterceptor.cs:line 37
   at Castle.DynamicProxy.AbstractInvocation.Proceed()
   at Abp.Runtime.Validation.Interception.ValidationInterceptor.Intercept(IInvocation invocation) in C:\work\Test\FrameDemo\ABP\Abp\Runtime\Validation\Interception\ValidationInterceptor.cs:line 33
   at Castle.DynamicProxy.AbstractInvocation.Proceed()
   at Castle.Proxies.TestAppServiceProxy.ContainPermission(String url, String userName, String pwd)
   at Frame.Mvc.MyHangfireAuthorizationFilter.<CheckPermission>d__3.MoveNext() in C:\work\Test\FrameDemo\Frame.Mvc\HangfireAuthorization\MyHangfireAuthorizationFilter.cs:line 75
--- End of stack trace from previous location where exception was thrown ---
   at System.Runtime.ExceptionServices.ExceptionDispatchInfo.Throw()
   at System.Runtime.CompilerServices.TaskAwaiter.HandleNonSuccessAndDebuggerNotification(Task task)
   at System.Runtime.CompilerServices.TaskAwaiter`1.GetResult()
   at Frame.Mvc.MyHangfireAuthorizationFilter.<Verification>d__2.MoveNext() in C:\work\Test\FrameDemo\Frame.Mvc\HangfireAuthorization\MyHangfireAuthorizationFilter.cs:line 66
   --- End of inner exception stack trace ---
   at System.Threading.Tasks.Task.ThrowIfExceptional(Boolean includeTaskCanceledExceptions)
   at System.Threading.Tasks.Task`1.GetResultCore(Boolean waitCompletionNotification)
   at Frame.Mvc.MyHangfireAuthorizationFilter.Authorize(DashboardContext context) in C:\work\Test\FrameDemo\Frame.Mvc\HangfireAuthorization\MyHangfireAuthorizationFilter.cs:line 41
   at Hangfire.Dashboard.AspNetCoreDashboardMiddleware.<Invoke>d__5.MoveNext()
--- End of stack trace from previous location where exception was thrown ---
   at System.Runtime.ExceptionServices.ExceptionDispatchInfo.Throw()
   at System.Runtime.CompilerServices.TaskAwaiter.HandleNonSuccessAndDebuggerNotification(Task task)
   at Microsoft.AspNetCore.Builder.Extensions.MapMiddleware.<Invoke>d__3.MoveNext()
--- End of stack trace from previous location where exception was thrown ---
   at System.Runtime.ExceptionServices.ExceptionDispatchInfo.Throw()
   at System.Runtime.CompilerServices.TaskAwaiter.HandleNonSuccessAndDebuggerNotification(Task task)
   at Microsoft.AspNetCore.Hosting.Internal.RequestServicesContainerMiddleware.<Invoke>d__3.MoveNext()
--- End of stack trace from previous location where exception was thrown ---
   at System.Runtime.ExceptionServices.ExceptionDispatchInfo.Throw()
   at System.Runtime.CompilerServices.TaskAwaiter.HandleNonSuccessAndDebuggerNotification(Task task)
   at Microsoft.AspNetCore.Server.Kestrel.Core.Internal.Http.Frame`1.<ProcessRequestsAsync>d__2.MoveNext()
---> (Inner Exception #0) Abp.Authorization.AbpAuthorizationException: Current user did not login to the application!
   at Abp.Authorization.AuthorizationHelper.<AuthorizeAsync>d__15.MoveNext() in C:\work\Test\FrameDemo\ABP\Abp\Authorization\AuthorizationHelper.cs:line 47
--- End of stack trace from previous location where exception was thrown ---
   at System.Runtime.ExceptionServices.ExceptionDispatchInfo.Throw()
   at System.Runtime.CompilerServices.TaskAwaiter.HandleNonSuccessAndDebuggerNotification(Task task)
   at Abp.Authorization.AuthorizationHelper.<CheckPermissions>d__18.MoveNext() in C:\work\Test\FrameDemo\ABP\Abp\Authorization\AuthorizationHelper.cs:line 107
--- End of stack trace from previous location where exception was thrown ---
   at System.Runtime.ExceptionServices.ExceptionDispatchInfo.Throw()
   at System.Runtime.CompilerServices.TaskAwaiter.HandleNonSuccessAndDebuggerNotification(Task task)
   at Abp.Authorization.AuthorizationHelper.<AuthorizeAsync>d__16.MoveNext() in C:\work\Test\FrameDemo\ABP\Abp\Authorization\AuthorizationHelper.cs:line 56
--- End of stack trace from previous location where exception was thrown ---
   at System.Runtime.ExceptionServices.ExceptionDispatchInfo.Throw()
   at System.Runtime.CompilerServices.TaskAwaiter.HandleNonSuccessAndDebuggerNotification(Task task)
   at Nito.AsyncEx.Synchronous.TaskExtensions.WaitAndUnwrapException(Task task)
   at System.Threading.ExecutionContext.Run(ExecutionContext executionContext, ContextCallback callback, Object state)
   at System.Threading.Tasks.Task.ExecuteWithThreadLocal(Task& currentTaskSlot)
--- End of stack trace from previous location where exception was thrown ---
   at System.Runtime.ExceptionServices.ExceptionDispatchInfo.Throw()
   at System.Runtime.CompilerServices.TaskAwaiter.HandleNonSuccessAndDebuggerNotification(Task task)
   at Nito.AsyncEx.Synchronous.TaskExtensions.WaitAndUnwrapException(Task task)
   at Nito.AsyncEx.AsyncContext.Run(Func`1 action)
   at Abp.Threading.AsyncHelper.RunSync(Func`1 action) in C:\work\Test\FrameDemo\ABP\Abp\Threading\AsyncHelper.cs:line 52
   at Abp.Authorization.AuthorizationHelperExtensions.Authorize(IAuthorizationHelper authorizationHelper, MethodInfo methodInfo, Type type) in C:\work\Test\FrameDemo\ABP\Abp\Authorization\AuthorizationHelperExtensions.cs:line 28
   at Abp.Authorization.AuthorizationInterceptor.Intercept(IInvocation invocation) in C:\work\Test\FrameDemo\ABP\Abp\Authorization\AuthorizationInterceptor.cs:line 19
   at Castle.DynamicProxy.AbstractInvocation.Proceed()
   at Abp.Domain.Uow.UnitOfWorkInterceptor.PerformAsyncUow(IInvocation invocation, UnitOfWorkOptions options) in C:\work\Test\FrameDemo\ABP\Abp\Domain\Uow\UnitOfWorkInterceptor.cs:line 83
   at Abp.Domain.Uow.UnitOfWorkInterceptor.PerformUow(IInvocation invocation, UnitOfWorkOptions options) in C:\work\Test\FrameDemo\ABP\Abp\Domain\Uow\UnitOfWorkInterceptor.cs:line 55
   at Abp.Domain.Uow.UnitOfWorkInterceptor.Intercept(IInvocation invocation) in C:\work\Test\FrameDemo\ABP\Abp\Domain\Uow\UnitOfWorkInterceptor.cs:line 48
   at Castle.DynamicProxy.AbstractInvocation.Proceed()
   at Abp.Auditing.AuditingInterceptor.Intercept(IInvocation invocation) in C:\work\Test\FrameDemo\ABP\Abp\Auditing\AuditingInterceptor.cs:line 37
   at Castle.DynamicProxy.AbstractInvocation.Proceed()
   at Abp.Runtime.Validation.Interception.ValidationInterceptor.Intercept(IInvocation invocation) in C:\work\Test\FrameDemo\ABP\Abp\Runtime\Validation\Interception\ValidationInterceptor.cs:line 33
   at Castle.DynamicProxy.AbstractInvocation.Proceed()
   at Castle.Proxies.TestAppServiceProxy.ContainPermission(String url, String userName, String pwd)
   at Frame.Mvc.MyHangfireAuthorizationFilter.<CheckPermission>d__3.MoveNext() in C:\work\Test\FrameDemo\Frame.Mvc\HangfireAuthorization\MyHangfireAuthorizationFilter.cs:line 75
--- End of stack trace from previous location where exception was thrown ---
   at System.Runtime.ExceptionServices.ExceptionDispatchInfo.Throw()
   at System.Runtime.CompilerServices.TaskAwaiter.HandleNonSuccessAndDebuggerNotification(Task task)
   at System.Runtime.CompilerServices.TaskAwaiter`1.GetResult()
   at Frame.Mvc.MyHangfireAuthorizationFilter.<Verification>d__2.MoveNext() in C:\work\Test\FrameDemo\Frame.Mvc\HangfireAuthorization\MyHangfireAuthorizationFilter.cs:line 66<---

2020-01-02 10:01:05,077 [8] ERROR Microsoft.AspNetCore.Server.Kestrel - Connection id "0HLSF4RV5CEE7", Request id "0HLSF4RV5CEE7:00000002": An unhandled exception was thrown by the application.
System.AggregateException: One or more errors occurred. (Current user did not login to the application!) ---> Abp.Authorization.AbpAuthorizationException: Current user did not login to the application!
   at Abp.Authorization.AuthorizationHelper.<AuthorizeAsync>d__15.MoveNext() in C:\work\Test\FrameDemo\ABP\Abp\Authorization\AuthorizationHelper.cs:line 47
--- End of stack trace from previous location where exception was thrown ---
   at System.Runtime.ExceptionServices.ExceptionDispatchInfo.Throw()
   at System.Runtime.CompilerServices.TaskAwaiter.HandleNonSuccessAndDebuggerNotification(Task task)
   at Abp.Authorization.AuthorizationHelper.<CheckPermissions>d__18.MoveNext() in C:\work\Test\FrameDemo\ABP\Abp\Authorization\AuthorizationHelper.cs:line 107
--- End of stack trace from previous location where exception was thrown ---
   at System.Runtime.ExceptionServices.ExceptionDispatchInfo.Throw()
   at System.Runtime.CompilerServices.TaskAwaiter.HandleNonSuccessAndDebuggerNotification(Task task)
   at Abp.Authorization.AuthorizationHelper.<AuthorizeAsync>d__16.MoveNext() in C:\work\Test\FrameDemo\ABP\Abp\Authorization\AuthorizationHelper.cs:line 56
--- End of stack trace from previous location where exception was thrown ---
   at System.Runtime.ExceptionServices.ExceptionDispatchInfo.Throw()
   at System.Runtime.CompilerServices.TaskAwaiter.HandleNonSuccessAndDebuggerNotification(Task task)
   at Nito.AsyncEx.Synchronous.TaskExtensions.WaitAndUnwrapException(Task task)
   at System.Threading.ExecutionContext.Run(ExecutionContext executionContext, ContextCallback callback, Object state)
   at System.Threading.Tasks.Task.ExecuteWithThreadLocal(Task& currentTaskSlot)
--- End of stack trace from previous location where exception was thrown ---
   at System.Runtime.ExceptionServices.ExceptionDispatchInfo.Throw()
   at System.Runtime.CompilerServices.TaskAwaiter.HandleNonSuccessAndDebuggerNotification(Task task)
   at Nito.AsyncEx.Synchronous.TaskExtensions.WaitAndUnwrapException(Task task)
   at Nito.AsyncEx.AsyncContext.Run(Func`1 action)
   at Abp.Threading.AsyncHelper.RunSync(Func`1 action) in C:\work\Test\FrameDemo\ABP\Abp\Threading\AsyncHelper.cs:line 52
   at Abp.Authorization.AuthorizationHelperExtensions.Authorize(IAuthorizationHelper authorizationHelper, MethodInfo methodInfo, Type type) in C:\work\Test\FrameDemo\ABP\Abp\Authorization\AuthorizationHelperExtensions.cs:line 28
   at Abp.Authorization.AuthorizationInterceptor.Intercept(IInvocation invocation) in C:\work\Test\FrameDemo\ABP\Abp\Authorization\AuthorizationInterceptor.cs:line 19
   at Castle.DynamicProxy.AbstractInvocation.Proceed()
   at Abp.Domain.Uow.UnitOfWorkInterceptor.PerformAsyncUow(IInvocation invocation, UnitOfWorkOptions options) in C:\work\Test\FrameDemo\ABP\Abp\Domain\Uow\UnitOfWorkInterceptor.cs:line 83
   at Abp.Domain.Uow.UnitOfWorkInterceptor.PerformUow(IInvocation invocation, UnitOfWorkOptions options) in C:\work\Test\FrameDemo\ABP\Abp\Domain\Uow\UnitOfWorkInterceptor.cs:line 55
   at Abp.Domain.Uow.UnitOfWorkInterceptor.Intercept(IInvocation invocation) in C:\work\Test\FrameDemo\ABP\Abp\Domain\Uow\UnitOfWorkInterceptor.cs:line 48
   at Castle.DynamicProxy.AbstractInvocation.Proceed()
   at Abp.Auditing.AuditingInterceptor.Intercept(IInvocation invocation) in C:\work\Test\FrameDemo\ABP\Abp\Auditing\AuditingInterceptor.cs:line 37
   at Castle.DynamicProxy.AbstractInvocation.Proceed()
   at Abp.Runtime.Validation.Interception.ValidationInterceptor.Intercept(IInvocation invocation) in C:\work\Test\FrameDemo\ABP\Abp\Runtime\Validation\Interception\ValidationInterceptor.cs:line 33
   at Castle.DynamicProxy.AbstractInvocation.Proceed()
   at Castle.Proxies.TestAppServiceProxy.ContainPermission(String url, String userName, String pwd)
   at Frame.Mvc.MyHangfireAuthorizationFilter.<CheckPermission>d__3.MoveNext() in C:\work\Test\FrameDemo\Frame.Mvc\HangfireAuthorization\MyHangfireAuthorizationFilter.cs:line 75
--- End of stack trace from previous location where exception was thrown ---
   at System.Runtime.ExceptionServices.ExceptionDispatchInfo.Throw()
   at System.Runtime.CompilerServices.TaskAwaiter.HandleNonSuccessAndDebuggerNotification(Task task)
   at System.Runtime.CompilerServices.TaskAwaiter`1.GetResult()
   at Frame.Mvc.MyHangfireAuthorizationFilter.<Verification>d__2.MoveNext() in C:\work\Test\FrameDemo\Frame.Mvc\HangfireAuthorization\MyHangfireAuthorizationFilter.cs:line 66
   --- End of inner exception stack trace ---
   at System.Threading.Tasks.Task.ThrowIfExceptional(Boolean includeTaskCanceledExceptions)
   at System.Threading.Tasks.Task`1.GetResultCore(Boolean waitCompletionNotification)
   at Frame.Mvc.MyHangfireAuthorizationFilter.Authorize(DashboardContext context) in C:\work\Test\FrameDemo\Frame.Mvc\HangfireAuthorization\MyHangfireAuthorizationFilter.cs:line 41
   at Hangfire.Dashboard.AspNetCoreDashboardMiddleware.<Invoke>d__5.MoveNext()
--- End of stack trace from previous location where exception was thrown ---
   at System.Runtime.ExceptionServices.ExceptionDispatchInfo.Throw()
   at System.Runtime.CompilerServices.TaskAwaiter.HandleNonSuccessAndDebuggerNotification(Task task)
   at Microsoft.AspNetCore.Builder.Extensions.MapMiddleware.<Invoke>d__3.MoveNext()
--- End of stack trace from previous location where exception was thrown ---
   at System.Runtime.ExceptionServices.ExceptionDispatchInfo.Throw()
   at System.Runtime.CompilerServices.TaskAwaiter.HandleNonSuccessAndDebuggerNotification(Task task)
   at Microsoft.AspNetCore.Hosting.Internal.RequestServicesContainerMiddleware.<Invoke>d__3.MoveNext()
--- End of stack trace from previous location where exception was thrown ---
   at System.Runtime.ExceptionServices.ExceptionDispatchInfo.Throw()
   at System.Runtime.CompilerServices.TaskAwaiter.HandleNonSuccessAndDebuggerNotification(Task task)
   at Microsoft.AspNetCore.Server.Kestrel.Core.Internal.Http.Frame`1.<ProcessRequestsAsync>d__2.MoveNext()
---> (Inner Exception #0) Abp.Authorization.AbpAuthorizationException: Current user did not login to the application!
   at Abp.Authorization.AuthorizationHelper.<AuthorizeAsync>d__15.MoveNext() in C:\work\Test\FrameDemo\ABP\Abp\Authorization\AuthorizationHelper.cs:line 47
--- End of stack trace from previous location where exception was thrown ---
   at System.Runtime.ExceptionServices.ExceptionDispatchInfo.Throw()
   at System.Runtime.CompilerServices.TaskAwaiter.HandleNonSuccessAndDebuggerNotification(Task task)
   at Abp.Authorization.AuthorizationHelper.<CheckPermissions>d__18.MoveNext() in C:\work\Test\FrameDemo\ABP\Abp\Authorization\AuthorizationHelper.cs:line 107
--- End of stack trace from previous location where exception was thrown ---
   at System.Runtime.ExceptionServices.ExceptionDispatchInfo.Throw()
   at System.Runtime.CompilerServices.TaskAwaiter.HandleNonSuccessAndDebuggerNotification(Task task)
   at Abp.Authorization.AuthorizationHelper.<AuthorizeAsync>d__16.MoveNext() in C:\work\Test\FrameDemo\ABP\Abp\Authorization\AuthorizationHelper.cs:line 56
--- End of stack trace from previous location where exception was thrown ---
   at System.Runtime.ExceptionServices.ExceptionDispatchInfo.Throw()
   at System.Runtime.CompilerServices.TaskAwaiter.HandleNonSuccessAndDebuggerNotification(Task task)
   at Nito.AsyncEx.Synchronous.TaskExtensions.WaitAndUnwrapException(Task task)
   at System.Threading.ExecutionContext.Run(ExecutionContext executionContext, ContextCallback callback, Object state)
   at System.Threading.Tasks.Task.ExecuteWithThreadLocal(Task& currentTaskSlot)
--- End of stack trace from previous location where exception was thrown ---
   at System.Runtime.ExceptionServices.ExceptionDispatchInfo.Throw()
   at System.Runtime.CompilerServices.TaskAwaiter.HandleNonSuccessAndDebuggerNotification(Task task)
   at Nito.AsyncEx.Synchronous.TaskExtensions.WaitAndUnwrapException(Task task)
   at Nito.AsyncEx.AsyncContext.Run(Func`1 action)
   at Abp.Threading.AsyncHelper.RunSync(Func`1 action) in C:\work\Test\FrameDemo\ABP\Abp\Threading\AsyncHelper.cs:line 52
   at Abp.Authorization.AuthorizationHelperExtensions.Authorize(IAuthorizationHelper authorizationHelper, MethodInfo methodInfo, Type type) in C:\work\Test\FrameDemo\ABP\Abp\Authorization\AuthorizationHelperExtensions.cs:line 28
   at Abp.Authorization.AuthorizationInterceptor.Intercept(IInvocation invocation) in C:\work\Test\FrameDemo\ABP\Abp\Authorization\AuthorizationInterceptor.cs:line 19
   at Castle.DynamicProxy.AbstractInvocation.Proceed()
   at Abp.Domain.Uow.UnitOfWorkInterceptor.PerformAsyncUow(IInvocation invocation, UnitOfWorkOptions options) in C:\work\Test\FrameDemo\ABP\Abp\Domain\Uow\UnitOfWorkInterceptor.cs:line 83
   at Abp.Domain.Uow.UnitOfWorkInterceptor.PerformUow(IInvocation invocation, UnitOfWorkOptions options) in C:\work\Test\FrameDemo\ABP\Abp\Domain\Uow\UnitOfWorkInterceptor.cs:line 55
   at Abp.Domain.Uow.UnitOfWorkInterceptor.Intercept(IInvocation invocation) in C:\work\Test\FrameDemo\ABP\Abp\Domain\Uow\UnitOfWorkInterceptor.cs:line 48
   at Castle.DynamicProxy.AbstractInvocation.Proceed()
   at Abp.Auditing.AuditingInterceptor.Intercept(IInvocation invocation) in C:\work\Test\FrameDemo\ABP\Abp\Auditing\AuditingInterceptor.cs:line 37
   at Castle.DynamicProxy.AbstractInvocation.Proceed()
   at Abp.Runtime.Validation.Interception.ValidationInterceptor.Intercept(IInvocation invocation) in C:\work\Test\FrameDemo\ABP\Abp\Runtime\Validation\Interception\ValidationInterceptor.cs:line 33
   at Castle.DynamicProxy.AbstractInvocation.Proceed()
   at Castle.Proxies.TestAppServiceProxy.ContainPermission(String url, String userName, String pwd)
   at Frame.Mvc.MyHangfireAuthorizationFilter.<CheckPermission>d__3.MoveNext() in C:\work\Test\FrameDemo\Frame.Mvc\HangfireAuthorization\MyHangfireAuthorizationFilter.cs:line 75
--- End of stack trace from previous location where exception was thrown ---
   at System.Runtime.ExceptionServices.ExceptionDispatchInfo.Throw()
   at System.Runtime.CompilerServices.TaskAwaiter.HandleNonSuccessAndDebuggerNotification(Task task)
   at System.Runtime.CompilerServices.TaskAwaiter`1.GetResult()
   at Frame.Mvc.MyHangfireAuthorizationFilter.<Verification>d__2.MoveNext() in C:\work\Test\FrameDemo\Frame.Mvc\HangfireAuthorization\MyHangfireAuthorizationFilter.cs:line 66<---

2020-01-02 14:51:56,423 [Worker #11] ERROR Hangfire.MySql.Core.JobQueue.MySqlJobQueue - Deadlock found when trying to get lock; try restarting transaction
MySql.Data.MySqlClient.MySqlException (0x80004005): Deadlock found when trying to get lock; try restarting transaction ---> MySql.Data.MySqlClient.MySqlException (0x80004005): Deadlock found when trying to get lock; try restarting transaction
   at System.Runtime.ExceptionServices.ExceptionDispatchInfo.Throw()
   at System.Runtime.CompilerServices.TaskAwaiter.HandleNonSuccessAndDebuggerNotification(Task task)
   at MySqlConnector.Core.ResultSet.<ReadResultSetHeaderAsync>d__1.MoveNext() in C:\projects\mysqlconnector\src\MySqlConnector\Core\ResultSet.cs:line 43
   at MySql.Data.MySqlClient.MySqlDataReader.ActivateResultSet(ResultSet resultSet) in C:\projects\mysqlconnector\src\MySqlConnector\MySql.Data.MySqlClient\MySqlDataReader.cs:line 81
   at MySql.Data.MySqlClient.MySqlDataReader.<ReadFirstResultSetAsync>d__94.MoveNext() in C:\projects\mysqlconnector\src\MySqlConnector\MySql.Data.MySqlClient\MySqlDataReader.cs:line 307
--- End of stack trace from previous location where exception was thrown ---
   at System.Runtime.ExceptionServices.ExceptionDispatchInfo.Throw()
   at System.Runtime.CompilerServices.TaskAwaiter.HandleNonSuccessAndDebuggerNotification(Task task)
   at MySql.Data.MySqlClient.MySqlDataReader.<CreateAsync>d__93.MoveNext() in C:\projects\mysqlconnector\src\MySqlConnector\MySql.Data.MySqlClient\MySqlDataReader.cs:line 297
--- End of stack trace from previous location where exception was thrown ---
   at System.Runtime.ExceptionServices.ExceptionDispatchInfo.Throw()
   at System.Runtime.CompilerServices.TaskAwaiter.HandleNonSuccessAndDebuggerNotification(Task task)
   at MySqlConnector.Core.TextCommandExecutor.<ExecuteReaderAsync>d__1.MoveNext() in C:\projects\mysqlconnector\src\MySqlConnector\Core\TextCommandExecutor.cs:line 37
--- End of stack trace from previous location where exception was thrown ---
   at System.Runtime.ExceptionServices.ExceptionDispatchInfo.Throw()
   at System.Runtime.CompilerServices.TaskAwaiter.HandleNonSuccessAndDebuggerNotification(Task task)
   at MySql.Data.MySqlClient.MySqlCommand.<ExecuteNonQueryAsync>d__61.MoveNext() in C:\projects\mysqlconnector\src\MySqlConnector\MySql.Data.MySqlClient\MySqlCommand.cs:line 276
--- End of stack trace from previous location where exception was thrown ---
   at System.Runtime.ExceptionServices.ExceptionDispatchInfo.Throw()
   at System.Runtime.CompilerServices.TaskAwaiter.HandleNonSuccessAndDebuggerNotification(Task task)
   at MySql.Data.MySqlClient.MySqlCommand.ExecuteNonQuery() in C:\projects\mysqlconnector\src\MySqlConnector\MySql.Data.MySqlClient\MySqlCommand.cs:line 77
   at Dapper.SqlMapper.ExecuteCommand(IDbConnection cnn, CommandDefinition& command, Action`2 paramReader) in C:\projects\dapper\Dapper\SqlMapper.cs:line 2827
   at Dapper.SqlMapper.ExecuteImpl(IDbConnection cnn, CommandDefinition& command) in C:\projects\dapper\Dapper\SqlMapper.cs:line 570
   at Hangfire.MySql.Core.JobQueue.MySqlJobQueue.Dequeue(String[] queues, CancellationToken cancellationToken)
2020-01-02 15:11:08,368 [Worker #9] ERROR Hangfire.MySql.Core.JobQueue.MySqlJobQueue - Deadlock found when trying to get lock; try restarting transaction
MySql.Data.MySqlClient.MySqlException (0x80004005): Deadlock found when trying to get lock; try restarting transaction ---> MySql.Data.MySqlClient.MySqlException (0x80004005): Deadlock found when trying to get lock; try restarting transaction
   at System.Runtime.ExceptionServices.ExceptionDispatchInfo.Throw()
   at System.Runtime.CompilerServices.TaskAwaiter.HandleNonSuccessAndDebuggerNotification(Task task)
   at MySqlConnector.Core.ResultSet.<ReadResultSetHeaderAsync>d__1.MoveNext() in C:\projects\mysqlconnector\src\MySqlConnector\Core\ResultSet.cs:line 43
   at MySql.Data.MySqlClient.MySqlDataReader.ActivateResultSet(ResultSet resultSet) in C:\projects\mysqlconnector\src\MySqlConnector\MySql.Data.MySqlClient\MySqlDataReader.cs:line 81
   at MySql.Data.MySqlClient.MySqlDataReader.<ReadFirstResultSetAsync>d__94.MoveNext() in C:\projects\mysqlconnector\src\MySqlConnector\MySql.Data.MySqlClient\MySqlDataReader.cs:line 307
--- End of stack trace from previous location where exception was thrown ---
   at System.Runtime.ExceptionServices.ExceptionDispatchInfo.Throw()
   at System.Runtime.CompilerServices.TaskAwaiter.HandleNonSuccessAndDebuggerNotification(Task task)
   at MySql.Data.MySqlClient.MySqlDataReader.<CreateAsync>d__93.MoveNext() in C:\projects\mysqlconnector\src\MySqlConnector\MySql.Data.MySqlClient\MySqlDataReader.cs:line 297
--- End of stack trace from previous location where exception was thrown ---
   at System.Runtime.ExceptionServices.ExceptionDispatchInfo.Throw()
   at System.Runtime.CompilerServices.TaskAwaiter.HandleNonSuccessAndDebuggerNotification(Task task)
   at MySqlConnector.Core.TextCommandExecutor.<ExecuteReaderAsync>d__1.MoveNext() in C:\projects\mysqlconnector\src\MySqlConnector\Core\TextCommandExecutor.cs:line 37
--- End of stack trace from previous location where exception was thrown ---
   at System.Runtime.ExceptionServices.ExceptionDispatchInfo.Throw()
   at System.Runtime.CompilerServices.TaskAwaiter.HandleNonSuccessAndDebuggerNotification(Task task)
   at MySql.Data.MySqlClient.MySqlCommand.<ExecuteNonQueryAsync>d__61.MoveNext() in C:\projects\mysqlconnector\src\MySqlConnector\MySql.Data.MySqlClient\MySqlCommand.cs:line 276
--- End of stack trace from previous location where exception was thrown ---
   at System.Runtime.ExceptionServices.ExceptionDispatchInfo.Throw()
   at System.Runtime.CompilerServices.TaskAwaiter.HandleNonSuccessAndDebuggerNotification(Task task)
   at MySql.Data.MySqlClient.MySqlCommand.ExecuteNonQuery() in C:\projects\mysqlconnector\src\MySqlConnector\MySql.Data.MySqlClient\MySqlCommand.cs:line 77
   at Dapper.SqlMapper.ExecuteCommand(IDbConnection cnn, CommandDefinition& command, Action`2 paramReader) in C:\projects\dapper\Dapper\SqlMapper.cs:line 2827
   at Dapper.SqlMapper.ExecuteImpl(IDbConnection cnn, CommandDefinition& command) in C:\projects\dapper\Dapper\SqlMapper.cs:line 570
   at Hangfire.MySql.Core.JobQueue.MySqlJobQueue.Dequeue(String[] queues, CancellationToken cancellationToken)
2020-01-02 15:50:04,053 [Worker #3] ERROR Hangfire.MySql.Core.JobQueue.MySqlJobQueue - Deadlock found when trying to get lock; try restarting transaction
MySql.Data.MySqlClient.MySqlException (0x80004005): Deadlock found when trying to get lock; try restarting transaction ---> MySql.Data.MySqlClient.MySqlException (0x80004005): Deadlock found when trying to get lock; try restarting transaction
   at System.Runtime.ExceptionServices.ExceptionDispatchInfo.Throw()
   at System.Runtime.CompilerServices.TaskAwaiter.HandleNonSuccessAndDebuggerNotification(Task task)
   at MySqlConnector.Core.ResultSet.<ReadResultSetHeaderAsync>d__1.MoveNext() in C:\projects\mysqlconnector\src\MySqlConnector\Core\ResultSet.cs:line 43
   at MySql.Data.MySqlClient.MySqlDataReader.ActivateResultSet(ResultSet resultSet) in C:\projects\mysqlconnector\src\MySqlConnector\MySql.Data.MySqlClient\MySqlDataReader.cs:line 81
   at MySql.Data.MySqlClient.MySqlDataReader.<ReadFirstResultSetAsync>d__94.MoveNext() in C:\projects\mysqlconnector\src\MySqlConnector\MySql.Data.MySqlClient\MySqlDataReader.cs:line 307
--- End of stack trace from previous location where exception was thrown ---
   at System.Runtime.ExceptionServices.ExceptionDispatchInfo.Throw()
   at System.Runtime.CompilerServices.TaskAwaiter.HandleNonSuccessAndDebuggerNotification(Task task)
   at MySql.Data.MySqlClient.MySqlDataReader.<CreateAsync>d__93.MoveNext() in C:\projects\mysqlconnector\src\MySqlConnector\MySql.Data.MySqlClient\MySqlDataReader.cs:line 297
--- End of stack trace from previous location where exception was thrown ---
   at System.Runtime.ExceptionServices.ExceptionDispatchInfo.Throw()
   at System.Runtime.CompilerServices.TaskAwaiter.HandleNonSuccessAndDebuggerNotification(Task task)
   at MySqlConnector.Core.TextCommandExecutor.<ExecuteReaderAsync>d__1.MoveNext() in C:\projects\mysqlconnector\src\MySqlConnector\Core\TextCommandExecutor.cs:line 37
--- End of stack trace from previous location where exception was thrown ---
   at System.Runtime.ExceptionServices.ExceptionDispatchInfo.Throw()
   at System.Runtime.CompilerServices.TaskAwaiter.HandleNonSuccessAndDebuggerNotification(Task task)
   at MySql.Data.MySqlClient.MySqlCommand.<ExecuteNonQueryAsync>d__61.MoveNext() in C:\projects\mysqlconnector\src\MySqlConnector\MySql.Data.MySqlClient\MySqlCommand.cs:line 276
--- End of stack trace from previous location where exception was thrown ---
   at System.Runtime.ExceptionServices.ExceptionDispatchInfo.Throw()
   at System.Runtime.CompilerServices.TaskAwaiter.HandleNonSuccessAndDebuggerNotification(Task task)
   at MySql.Data.MySqlClient.MySqlCommand.ExecuteNonQuery() in C:\projects\mysqlconnector\src\MySqlConnector\MySql.Data.MySqlClient\MySqlCommand.cs:line 77
   at Dapper.SqlMapper.ExecuteCommand(IDbConnection cnn, CommandDefinition& command, Action`2 paramReader) in C:\projects\dapper\Dapper\SqlMapper.cs:line 2827
   at Dapper.SqlMapper.ExecuteImpl(IDbConnection cnn, CommandDefinition& command) in C:\projects\dapper\Dapper\SqlMapper.cs:line 570
   at Hangfire.MySql.Core.JobQueue.MySqlJobQueue.Dequeue(String[] queues, CancellationToken cancellationToken)
2020-01-02 15:58:55,614 [7] ERROR Microsoft.AspNetCore.Server.Kestrel - Connection id "0HLSFB6B4Q50H", Request id "0HLSFB6B4Q50H:00000003": An unhandled exception was thrown by the application.
System.NotSupportedException: Ambiguous HTTP method for action - Frame.Mvc.Controllers.HomeController.Index (Frame.Mvc). Actions require an explicit HttpMethod binding for Swagger 2.0
   at Swashbuckle.AspNetCore.SwaggerGen.SwaggerGenerator.CreatePathItem(IEnumerable`1 apiDescriptions, ISchemaRegistry schemaRegistry)
   at System.Linq.Enumerable.ToDictionary[TSource,TKey,TElement](IEnumerable`1 source, Func`2 keySelector, Func`2 elementSelector, IEqualityComparer`1 comparer)
   at Swashbuckle.AspNetCore.SwaggerGen.SwaggerGenerator.CreatePathItems(IEnumerable`1 apiDescriptions, ISchemaRegistry schemaRegistry)
   at Swashbuckle.AspNetCore.SwaggerGen.SwaggerGenerator.GetSwagger(String documentName, String host, String basePath, String[] schemes)
   at Swashbuckle.AspNetCore.Swagger.SwaggerMiddleware.<Invoke>d__6.MoveNext()
--- End of stack trace from previous location where exception was thrown ---
   at System.Runtime.ExceptionServices.ExceptionDispatchInfo.Throw()
   at System.Runtime.CompilerServices.TaskAwaiter.HandleNonSuccessAndDebuggerNotification(Task task)
   at Abp.AspNetCore.Security.AbpSecurityHeadersMiddleware.<Invoke>d__2.MoveNext() in C:\work\Test\FrameDemo\ABP\Abp.AspNetCore\AspNetCore\Security\AbpSecurityHeadersMiddleware.cs:line 26
--- End of stack trace from previous location where exception was thrown ---
   at System.Runtime.ExceptionServices.ExceptionDispatchInfo.Throw()
   at System.Runtime.CompilerServices.TaskAwaiter.HandleNonSuccessAndDebuggerNotification(Task task)
   at Microsoft.AspNetCore.Localization.RequestLocalizationMiddleware.<Invoke>d__5.MoveNext()
--- End of stack trace from previous location where exception was thrown ---
   at System.Runtime.ExceptionServices.ExceptionDispatchInfo.Throw()
   at System.Runtime.CompilerServices.TaskAwaiter.HandleNonSuccessAndDebuggerNotification(Task task)
   at Microsoft.AspNetCore.Builder.Extensions.MapMiddleware.<Invoke>d__3.MoveNext()
--- End of stack trace from previous location where exception was thrown ---
   at System.Runtime.ExceptionServices.ExceptionDispatchInfo.Throw()
   at System.Runtime.CompilerServices.TaskAwaiter.HandleNonSuccessAndDebuggerNotification(Task task)
   at Microsoft.AspNetCore.Hosting.Internal.RequestServicesContainerMiddleware.<Invoke>d__3.MoveNext()
--- End of stack trace from previous location where exception was thrown ---
   at System.Runtime.ExceptionServices.ExceptionDispatchInfo.Throw()
   at System.Runtime.CompilerServices.TaskAwaiter.HandleNonSuccessAndDebuggerNotification(Task task)
   at Microsoft.AspNetCore.Server.Kestrel.Core.Internal.Http.Frame`1.<ProcessRequestsAsync>d__2.MoveNext()
2020-01-02 16:30:33,021 [5] ERROR Abp.AspNetCore.Mvc.ExceptionHandling.AbpExceptionFilter - Object reference not set to an instance of an object.
System.NullReferenceException: Object reference not set to an instance of an object.
   at Frame.Application.TestAppService.<ContainPermission>d__10.MoveNext()
--- End of stack trace from previous location where exception was thrown ---
   at System.Runtime.ExceptionServices.ExceptionDispatchInfo.Throw()
   at System.Runtime.CompilerServices.TaskAwaiter.HandleNonSuccessAndDebuggerNotification(Task task)
   at lambda_method(Closure , Object )
   at Microsoft.AspNetCore.Mvc.Internal.ActionMethodExecutor.AwaitableObjectResultExecutor.<Execute>d__0.MoveNext()
--- End of stack trace from previous location where exception was thrown ---
   at System.Runtime.ExceptionServices.ExceptionDispatchInfo.Throw()
   at System.Runtime.CompilerServices.TaskAwaiter.HandleNonSuccessAndDebuggerNotification(Task task)
   at Microsoft.AspNetCore.Mvc.Internal.ControllerActionInvoker.<InvokeActionMethodAsync>d__12.MoveNext()
--- End of stack trace from previous location where exception was thrown ---
   at System.Runtime.ExceptionServices.ExceptionDispatchInfo.Throw()
   at System.Runtime.CompilerServices.TaskAwaiter.HandleNonSuccessAndDebuggerNotification(Task task)
   at Microsoft.AspNetCore.Mvc.Internal.ControllerActionInvoker.<InvokeNextActionFilterAsync>d__10.MoveNext()
--- End of stack trace from previous location where exception was thrown ---
   at System.Runtime.ExceptionServices.ExceptionDispatchInfo.Throw()
   at Microsoft.AspNetCore.Mvc.Internal.ControllerActionInvoker.Rethrow(ActionExecutedContext context)
   at Microsoft.AspNetCore.Mvc.Internal.ControllerActionInvoker.Next(State& next, Scope& scope, Object& state, Boolean& isCompleted)
   at Microsoft.AspNetCore.Mvc.Internal.ControllerActionInvoker.<InvokeInnerFilterAsync>d__13.MoveNext()
--- End of stack trace from previous location where exception was thrown ---
   at System.Runtime.ExceptionServices.ExceptionDispatchInfo.Throw()
   at System.Runtime.CompilerServices.TaskAwaiter.HandleNonSuccessAndDebuggerNotification(Task task)
   at Microsoft.AspNetCore.Mvc.Internal.ResourceInvoker.<InvokeNextExceptionFilterAsync>d__24.MoveNext()
2020-01-02 16:49:22,516 [44] ERROR Microsoft.AspNetCore.Server.Kestrel - Connection id "0HLSFC1NS49M9", Request id "0HLSFC1NS49M9:00000005": An unhandled exception was thrown by the application.
System.AggregateException: One or more errors occurred. (Current user did not login to the application!) ---> Abp.Authorization.AbpAuthorizationException: Current user did not login to the application!
   at Abp.Authorization.AuthorizationHelper.<AuthorizeAsync>d__15.MoveNext() in C:\work\Test\FrameDemo\ABP\Abp\Authorization\AuthorizationHelper.cs:line 47
--- End of stack trace from previous location where exception was thrown ---
   at System.Runtime.ExceptionServices.ExceptionDispatchInfo.Throw()
   at System.Runtime.CompilerServices.TaskAwaiter.HandleNonSuccessAndDebuggerNotification(Task task)
   at Abp.Authorization.AuthorizationHelper.<CheckPermissions>d__18.MoveNext() in C:\work\Test\FrameDemo\ABP\Abp\Authorization\AuthorizationHelper.cs:line 107
--- End of stack trace from previous location where exception was thrown ---
   at System.Runtime.ExceptionServices.ExceptionDispatchInfo.Throw()
   at System.Runtime.CompilerServices.TaskAwaiter.HandleNonSuccessAndDebuggerNotification(Task task)
   at Abp.Authorization.AuthorizationHelper.<AuthorizeAsync>d__16.MoveNext() in C:\work\Test\FrameDemo\ABP\Abp\Authorization\AuthorizationHelper.cs:line 56
--- End of stack trace from previous location where exception was thrown ---
   at System.Runtime.ExceptionServices.ExceptionDispatchInfo.Throw()
   at System.Runtime.CompilerServices.TaskAwaiter.HandleNonSuccessAndDebuggerNotification(Task task)
   at Nito.AsyncEx.Synchronous.TaskExtensions.WaitAndUnwrapException(Task task)
   at System.Threading.ExecutionContext.Run(ExecutionContext executionContext, ContextCallback callback, Object state)
   at System.Threading.Tasks.Task.ExecuteWithThreadLocal(Task& currentTaskSlot)
--- End of stack trace from previous location where exception was thrown ---
   at System.Runtime.ExceptionServices.ExceptionDispatchInfo.Throw()
   at System.Runtime.CompilerServices.TaskAwaiter.HandleNonSuccessAndDebuggerNotification(Task task)
   at Nito.AsyncEx.Synchronous.TaskExtensions.WaitAndUnwrapException(Task task)
   at Nito.AsyncEx.AsyncContext.Run(Func`1 action)
   at Abp.Threading.AsyncHelper.RunSync(Func`1 action) in C:\work\Test\FrameDemo\ABP\Abp\Threading\AsyncHelper.cs:line 52
   at Abp.Authorization.AuthorizationHelperExtensions.Authorize(IAuthorizationHelper authorizationHelper, MethodInfo methodInfo, Type type) in C:\work\Test\FrameDemo\ABP\Abp\Authorization\AuthorizationHelperExtensions.cs:line 28
   at Abp.Authorization.AuthorizationInterceptor.Intercept(IInvocation invocation) in C:\work\Test\FrameDemo\ABP\Abp\Authorization\AuthorizationInterceptor.cs:line 19
   at Castle.DynamicProxy.AbstractInvocation.Proceed()
   at Abp.Domain.Uow.UnitOfWorkInterceptor.PerformAsyncUow(IInvocation invocation, UnitOfWorkOptions options) in C:\work\Test\FrameDemo\ABP\Abp\Domain\Uow\UnitOfWorkInterceptor.cs:line 83
   at Abp.Domain.Uow.UnitOfWorkInterceptor.PerformUow(IInvocation invocation, UnitOfWorkOptions options) in C:\work\Test\FrameDemo\ABP\Abp\Domain\Uow\UnitOfWorkInterceptor.cs:line 55
   at Abp.Domain.Uow.UnitOfWorkInterceptor.Intercept(IInvocation invocation) in C:\work\Test\FrameDemo\ABP\Abp\Domain\Uow\UnitOfWorkInterceptor.cs:line 48
   at Castle.DynamicProxy.AbstractInvocation.Proceed()
   at Abp.Auditing.AuditingInterceptor.Intercept(IInvocation invocation) in C:\work\Test\FrameDemo\ABP\Abp\Auditing\AuditingInterceptor.cs:line 37
   at Castle.DynamicProxy.AbstractInvocation.Proceed()
   at Abp.Runtime.Validation.Interception.ValidationInterceptor.Intercept(IInvocation invocation) in C:\work\Test\FrameDemo\ABP\Abp\Runtime\Validation\Interception\ValidationInterceptor.cs:line 33
   at Castle.DynamicProxy.AbstractInvocation.Proceed()
   at Castle.Proxies.TestAppServiceProxy.ContainPermission(String url, String userName, String pwd)
   at Frame.Mvc.MyHangfireAuthorizationFilter.<CheckPermission>d__3.MoveNext() in C:\work\Test\FrameDemo\Frame.Mvc\HangfireAuthorization\MyHangfireAuthorizationFilter.cs:line 76
--- End of stack trace from previous location where exception was thrown ---
   at System.Runtime.ExceptionServices.ExceptionDispatchInfo.Throw()
   at System.Runtime.CompilerServices.TaskAwaiter.HandleNonSuccessAndDebuggerNotification(Task task)
   at System.Runtime.CompilerServices.TaskAwaiter`1.GetResult()
   at Frame.Mvc.MyHangfireAuthorizationFilter.<Verification>d__2.MoveNext() in C:\work\Test\FrameDemo\Frame.Mvc\HangfireAuthorization\MyHangfireAuthorizationFilter.cs:line 66
   --- End of inner exception stack trace ---
   at System.Threading.Tasks.Task.ThrowIfExceptional(Boolean includeTaskCanceledExceptions)
   at System.Threading.Tasks.Task`1.GetResultCore(Boolean waitCompletionNotification)
   at Frame.Mvc.MyHangfireAuthorizationFilter.Authorize(DashboardContext context) in C:\work\Test\FrameDemo\Frame.Mvc\HangfireAuthorization\MyHangfireAuthorizationFilter.cs:line 41
   at Hangfire.Dashboard.AspNetCoreDashboardMiddleware.<Invoke>d__5.MoveNext()
--- End of stack trace from previous location where exception was thrown ---
   at System.Runtime.ExceptionServices.ExceptionDispatchInfo.Throw()
   at System.Runtime.CompilerServices.TaskAwaiter.HandleNonSuccessAndDebuggerNotification(Task task)
   at Microsoft.AspNetCore.Builder.Extensions.MapMiddleware.<Invoke>d__3.MoveNext()
--- End of stack trace from previous location where exception was thrown ---
   at System.Runtime.ExceptionServices.ExceptionDispatchInfo.Throw()
   at System.Runtime.CompilerServices.TaskAwaiter.HandleNonSuccessAndDebuggerNotification(Task task)
   at Microsoft.AspNetCore.Hosting.Internal.RequestServicesContainerMiddleware.<Invoke>d__3.MoveNext()
--- End of stack trace from previous location where exception was thrown ---
   at System.Runtime.ExceptionServices.ExceptionDispatchInfo.Throw()
   at System.Runtime.CompilerServices.TaskAwaiter.HandleNonSuccessAndDebuggerNotification(Task task)
   at Microsoft.AspNetCore.Server.Kestrel.Core.Internal.Http.Frame`1.<ProcessRequestsAsync>d__2.MoveNext()
---> (Inner Exception #0) Abp.Authorization.AbpAuthorizationException: Current user did not login to the application!
   at Abp.Authorization.AuthorizationHelper.<AuthorizeAsync>d__15.MoveNext() in C:\work\Test\FrameDemo\ABP\Abp\Authorization\AuthorizationHelper.cs:line 47
--- End of stack trace from previous location where exception was thrown ---
   at System.Runtime.ExceptionServices.ExceptionDispatchInfo.Throw()
   at System.Runtime.CompilerServices.TaskAwaiter.HandleNonSuccessAndDebuggerNotification(Task task)
   at Abp.Authorization.AuthorizationHelper.<CheckPermissions>d__18.MoveNext() in C:\work\Test\FrameDemo\ABP\Abp\Authorization\AuthorizationHelper.cs:line 107
--- End of stack trace from previous location where exception was thrown ---
   at System.Runtime.ExceptionServices.ExceptionDispatchInfo.Throw()
   at System.Runtime.CompilerServices.TaskAwaiter.HandleNonSuccessAndDebuggerNotification(Task task)
   at Abp.Authorization.AuthorizationHelper.<AuthorizeAsync>d__16.MoveNext() in C:\work\Test\FrameDemo\ABP\Abp\Authorization\AuthorizationHelper.cs:line 56
--- End of stack trace from previous location where exception was thrown ---
   at System.Runtime.ExceptionServices.ExceptionDispatchInfo.Throw()
   at System.Runtime.CompilerServices.TaskAwaiter.HandleNonSuccessAndDebuggerNotification(Task task)
   at Nito.AsyncEx.Synchronous.TaskExtensions.WaitAndUnwrapException(Task task)
   at System.Threading.ExecutionContext.Run(ExecutionContext executionContext, ContextCallback callback, Object state)
   at System.Threading.Tasks.Task.ExecuteWithThreadLocal(Task& currentTaskSlot)
--- End of stack trace from previous location where exception was thrown ---
   at System.Runtime.ExceptionServices.ExceptionDispatchInfo.Throw()
   at System.Runtime.CompilerServices.TaskAwaiter.HandleNonSuccessAndDebuggerNotification(Task task)
   at Nito.AsyncEx.Synchronous.TaskExtensions.WaitAndUnwrapException(Task task)
   at Nito.AsyncEx.AsyncContext.Run(Func`1 action)
   at Abp.Threading.AsyncHelper.RunSync(Func`1 action) in C:\work\Test\FrameDemo\ABP\Abp\Threading\AsyncHelper.cs:line 52
   at Abp.Authorization.AuthorizationHelperExtensions.Authorize(IAuthorizationHelper authorizationHelper, MethodInfo methodInfo, Type type) in C:\work\Test\FrameDemo\ABP\Abp\Authorization\AuthorizationHelperExtensions.cs:line 28
   at Abp.Authorization.AuthorizationInterceptor.Intercept(IInvocation invocation) in C:\work\Test\FrameDemo\ABP\Abp\Authorization\AuthorizationInterceptor.cs:line 19
   at Castle.DynamicProxy.AbstractInvocation.Proceed()
   at Abp.Domain.Uow.UnitOfWorkInterceptor.PerformAsyncUow(IInvocation invocation, UnitOfWorkOptions options) in C:\work\Test\FrameDemo\ABP\Abp\Domain\Uow\UnitOfWorkInterceptor.cs:line 83
   at Abp.Domain.Uow.UnitOfWorkInterceptor.PerformUow(IInvocation invocation, UnitOfWorkOptions options) in C:\work\Test\FrameDemo\ABP\Abp\Domain\Uow\UnitOfWorkInterceptor.cs:line 55
   at Abp.Domain.Uow.UnitOfWorkInterceptor.Intercept(IInvocation invocation) in C:\work\Test\FrameDemo\ABP\Abp\Domain\Uow\UnitOfWorkInterceptor.cs:line 48
   at Castle.DynamicProxy.AbstractInvocation.Proceed()
   at Abp.Auditing.AuditingInterceptor.Intercept(IInvocation invocation) in C:\work\Test\FrameDemo\ABP\Abp\Auditing\AuditingInterceptor.cs:line 37
   at Castle.DynamicProxy.AbstractInvocation.Proceed()
   at Abp.Runtime.Validation.Interception.ValidationInterceptor.Intercept(IInvocation invocation) in C:\work\Test\FrameDemo\ABP\Abp\Runtime\Validation\Interception\ValidationInterceptor.cs:line 33
   at Castle.DynamicProxy.AbstractInvocation.Proceed()
   at Castle.Proxies.TestAppServiceProxy.ContainPermission(String url, String userName, String pwd)
   at Frame.Mvc.MyHangfireAuthorizationFilter.<CheckPermission>d__3.MoveNext() in C:\work\Test\FrameDemo\Frame.Mvc\HangfireAuthorization\MyHangfireAuthorizationFilter.cs:line 76
--- End of stack trace from previous location where exception was thrown ---
   at System.Runtime.ExceptionServices.ExceptionDispatchInfo.Throw()
   at System.Runtime.CompilerServices.TaskAwaiter.HandleNonSuccessAndDebuggerNotification(Task task)
   at System.Runtime.CompilerServices.TaskAwaiter`1.GetResult()
   at Frame.Mvc.MyHangfireAuthorizationFilter.<Verification>d__2.MoveNext() in C:\work\Test\FrameDemo\Frame.Mvc\HangfireAuthorization\MyHangfireAuthorizationFilter.cs:line 66<---

2020-01-02 18:38:34,788 [45] ERROR Microsoft.AspNetCore.Server.Kestrel - Connection id "0HLSFDUB0NV00", Request id "0HLSFDUB0NV00:00000010": An unhandled exception was thrown by the application.
System.InvalidOperationException: StatusCode cannot be set because the response has already started.
   at Microsoft.AspNetCore.Server.Kestrel.Core.Internal.Http.Frame.ThrowResponseAlreadyStartedException(String value)
   at Microsoft.AspNetCore.Server.Kestrel.Core.Internal.Http.Frame.set_StatusCode(Int32 value)
   at Microsoft.AspNetCore.Server.Kestrel.Core.Internal.Http.Frame.Microsoft.AspNetCore.Http.Features.IHttpResponseFeature.set_StatusCode(Int32 value)
   at Hangfire.Dashboard.AspNetCoreDashboardMiddleware.<Invoke>d__5.MoveNext()
--- End of stack trace from previous location where exception was thrown ---
   at System.Runtime.ExceptionServices.ExceptionDispatchInfo.Throw()
   at System.Runtime.CompilerServices.TaskAwaiter.HandleNonSuccessAndDebuggerNotification(Task task)
   at Microsoft.AspNetCore.Builder.Extensions.MapMiddleware.<Invoke>d__3.MoveNext()
--- End of stack trace from previous location where exception was thrown ---
   at System.Runtime.ExceptionServices.ExceptionDispatchInfo.Throw()
   at System.Runtime.CompilerServices.TaskAwaiter.HandleNonSuccessAndDebuggerNotification(Task task)
   at Microsoft.AspNetCore.Hosting.Internal.RequestServicesContainerMiddleware.<Invoke>d__3.MoveNext()
--- End of stack trace from previous location where exception was thrown ---
   at System.Runtime.ExceptionServices.ExceptionDispatchInfo.Throw()
   at System.Runtime.CompilerServices.TaskAwaiter.HandleNonSuccessAndDebuggerNotification(Task task)
   at Microsoft.AspNetCore.Server.Kestrel.Core.Internal.Http.Frame`1.<ProcessRequestsAsync>d__2.MoveNext()
2020-01-02 18:38:42,140 [5] ERROR Microsoft.AspNetCore.Server.Kestrel - Connection id "0HLSFDUB0NV01", Request id "0HLSFDUB0NV01:00000003": An unhandled exception was thrown by the application.
System.InvalidOperationException: StatusCode cannot be set because the response has already started.
   at Microsoft.AspNetCore.Server.Kestrel.Core.Internal.Http.Frame.ThrowResponseAlreadyStartedException(String value)
   at Microsoft.AspNetCore.Server.Kestrel.Core.Internal.Http.Frame.set_StatusCode(Int32 value)
   at Microsoft.AspNetCore.Server.Kestrel.Core.Internal.Http.Frame.Microsoft.AspNetCore.Http.Features.IHttpResponseFeature.set_StatusCode(Int32 value)
   at Hangfire.Dashboard.AspNetCoreDashboardMiddleware.<Invoke>d__5.MoveNext()
--- End of stack trace from previous location where exception was thrown ---
   at System.Runtime.ExceptionServices.ExceptionDispatchInfo.Throw()
   at System.Runtime.CompilerServices.TaskAwaiter.HandleNonSuccessAndDebuggerNotification(Task task)
   at Microsoft.AspNetCore.Builder.Extensions.MapMiddleware.<Invoke>d__3.MoveNext()
--- End of stack trace from previous location where exception was thrown ---
   at System.Runtime.ExceptionServices.ExceptionDispatchInfo.Throw()
   at System.Runtime.CompilerServices.TaskAwaiter.HandleNonSuccessAndDebuggerNotification(Task task)
   at Microsoft.AspNetCore.Hosting.Internal.RequestServicesContainerMiddleware.<Invoke>d__3.MoveNext()
--- End of stack trace from previous location where exception was thrown ---
   at System.Runtime.ExceptionServices.ExceptionDispatchInfo.Throw()
   at System.Runtime.CompilerServices.TaskAwaiter.HandleNonSuccessAndDebuggerNotification(Task task)
   at Microsoft.AspNetCore.Server.Kestrel.Core.Internal.Http.Frame`1.<ProcessRequestsAsync>d__2.MoveNext()
