2019-12-31 17:32:43,074 [49] ERROR Microsoft.AspNetCore.Server.Kestrel - Connection id "0HLSDQFMUELGC", Request id "0HLSDQFMUELGC:00000005": An unhandled exception was thrown by the application.
System.ObjectDisposedException: Cannot access a disposed object. A common cause of this error is disposing a context that was resolved from dependency injection and then later trying to use the same context instance elsewhere in your application. This may occur if you are calling Dispose() on the context, or wrapping the context in a using statement. If you are using dependency injection, you should let the dependency injection container take care of disposing context instances.
Object name: 'NapManageDbContext'.
   at Microsoft.EntityFrameworkCore.DbContext.CheckDisposed()
   at Microsoft.EntityFrameworkCore.DbContext.get_DbContextDependencies()
   at Microsoft.EntityFrameworkCore.DbContext.get_Model()
   at Microsoft.EntityFrameworkCore.Internal.InternalDbSet`1.get_EntityType()
   at Microsoft.EntityFrameworkCore.Internal.InternalDbSet`1.get_EntityQueryable()
   at Microsoft.EntityFrameworkCore.Internal.InternalDbSet`1.System.Linq.IQueryable.get_Provider()
   at System.Linq.Queryable.Where[TSource](IQueryable`1 source, Expression`1 predicate)
   at Frame.Mvc.MyHangfireAuthorizationFilter.CheckPermission(DashboardContext context, Int64 userId) in C:\work\Test\FrameDemo\Frame.Mvc\HangfireAuthorization\MyHangfireAuthorizationFilter.cs:line 50
   at Frame.Mvc.MyHangfireAuthorizationFilter.Authorize(DashboardContext context) in C:\work\Test\FrameDemo\Frame.Mvc\HangfireAuthorization\MyHangfireAuthorizationFilter.cs:line 21
   at Hangfire.Dashboard.AspNetCoreDashboardMiddleware.<Invoke>d__5.MoveNext()
--- End of stack trace from previous location where exception was thrown ---
   at System.Runtime.ExceptionServices.ExceptionDispatchInfo.Throw()
   at System.Runtime.CompilerServices.TaskAwaiter.HandleNonSuccessAndDebuggerNotification(Task task)
   at Microsoft.AspNetCore.Builder.Extensions.MapMiddleware.<Invoke>d__3.MoveNext()
--- End of stack trace from previous location where exception was thrown ---
   at System.Runtime.ExceptionServices.ExceptionDispatchInfo.Throw()
   at System.Runtime.CompilerServices.TaskAwaiter.HandleNonSuccessAndDebuggerNotification(Task task)
   at Microsoft.AspNetCore.Hosting.Internal.RequestServicesContainerMiddleware.<Invoke>d__3.MoveNext()
--- End of stack trace from previous location where exception was thrown ---
   at System.Runtime.ExceptionServices.ExceptionDispatchInfo.Throw()
   at System.Runtime.CompilerServices.TaskAwaiter.HandleNonSuccessAndDebuggerNotification(Task task)
   at Microsoft.AspNetCore.Server.Kestrel.Core.Internal.Http.Frame`1.<ProcessRequestsAsync>d__2.MoveNext()
2019-12-31 17:56:19,682 [44] ERROR Microsoft.AspNetCore.Server.Kestrel - Connection id "0HLSDQU6K6TBV", Request id "0HLSDQU6K6TBV:00000005": An unhandled exception was thrown by the application.
System.InvalidOperationException: StatusCode cannot be set because the response has already started.
   at Microsoft.AspNetCore.Server.Kestrel.Core.Internal.Http.Frame.ThrowResponseAlreadyStartedException(String value)
   at Microsoft.AspNetCore.Server.Kestrel.Core.Internal.Http.Frame.set_StatusCode(Int32 value)
   at Microsoft.AspNetCore.Server.Kestrel.Core.Internal.Http.Frame.Microsoft.AspNetCore.Http.Features.IHttpResponseFeature.set_StatusCode(Int32 value)
   at Hangfire.Dashboard.AspNetCoreDashboardMiddleware.<Invoke>d__5.MoveNext()
--- End of stack trace from previous location where exception was thrown ---
   at System.Runtime.ExceptionServices.ExceptionDispatchInfo.Throw()
   at System.Runtime.CompilerServices.TaskAwaiter.HandleNonSuccessAndDebuggerNotification(Task task)
   at Microsoft.AspNetCore.Builder.Extensions.MapMiddleware.<Invoke>d__3.MoveNext()
--- End of stack trace from previous location where exception was thrown ---
   at System.Runtime.ExceptionServices.ExceptionDispatchInfo.Throw()
   at System.Runtime.CompilerServices.TaskAwaiter.HandleNonSuccessAndDebuggerNotification(Task task)
   at Microsoft.AspNetCore.Hosting.Internal.RequestServicesContainerMiddleware.<Invoke>d__3.MoveNext()
--- End of stack trace from previous location where exception was thrown ---
   at System.Runtime.ExceptionServices.ExceptionDispatchInfo.Throw()
   at System.Runtime.CompilerServices.TaskAwaiter.HandleNonSuccessAndDebuggerNotification(Task task)
   at Microsoft.AspNetCore.Server.Kestrel.Core.Internal.Http.Frame`1.<ProcessRequestsAsync>d__2.MoveNext()
2019-12-31 17:58:14,476 [6] ERROR Microsoft.AspNetCore.Server.Kestrel - Connection id "0HLSDQU6K6TC3", Request id "0HLSDQU6K6TC3:00000001": An unhandled exception was thrown by the application.
System.InvalidOperationException: StatusCode cannot be set because the response has already started.
   at Microsoft.AspNetCore.Server.Kestrel.Core.Internal.Http.Frame.ThrowResponseAlreadyStartedException(String value)
   at Microsoft.AspNetCore.Server.Kestrel.Core.Internal.Http.Frame.set_StatusCode(Int32 value)
   at Microsoft.AspNetCore.Server.Kestrel.Core.Internal.Http.Frame.Microsoft.AspNetCore.Http.Features.IHttpResponseFeature.set_StatusCode(Int32 value)
   at Frame.Mvc.MyHangfireAuthorizationFilter.SetChallengeResponse(HttpContext httpContext)
   at Frame.Mvc.MyHangfireAuthorizationFilter.Authorize(DashboardContext context)
   at Hangfire.Dashboard.AspNetCoreDashboardMiddleware.<Invoke>d__5.MoveNext()
--- End of stack trace from previous location where exception was thrown ---
   at System.Runtime.ExceptionServices.ExceptionDispatchInfo.Throw()
   at System.Runtime.CompilerServices.TaskAwaiter.HandleNonSuccessAndDebuggerNotification(Task task)
   at Microsoft.AspNetCore.Builder.Extensions.MapMiddleware.<Invoke>d__3.MoveNext()
--- End of stack trace from previous location where exception was thrown ---
   at System.Runtime.ExceptionServices.ExceptionDispatchInfo.Throw()
   at System.Runtime.CompilerServices.TaskAwaiter.HandleNonSuccessAndDebuggerNotification(Task task)
   at Microsoft.AspNetCore.Hosting.Internal.RequestServicesContainerMiddleware.<Invoke>d__3.MoveNext()
--- End of stack trace from previous location where exception was thrown ---
   at System.Runtime.ExceptionServices.ExceptionDispatchInfo.Throw()
   at System.Runtime.CompilerServices.TaskAwaiter.HandleNonSuccessAndDebuggerNotification(Task task)
   at Microsoft.AspNetCore.Server.Kestrel.Core.Internal.Http.Frame`1.<ProcessRequestsAsync>d__2.MoveNext()
2019-12-31 18:00:41,234 [45] ERROR Microsoft.AspNetCore.Server.Kestrel - Connection id "0HLSDR0IA22Q4", Request id "0HLSDR0IA22Q4:00000004": An unhandled exception was thrown by the application.
System.InvalidOperationException: StatusCode cannot be set because the response has already started.
   at Microsoft.AspNetCore.Server.Kestrel.Core.Internal.Http.Frame.ThrowResponseAlreadyStartedException(String value)
   at Microsoft.AspNetCore.Server.Kestrel.Core.Internal.Http.Frame.set_StatusCode(Int32 value)
   at Microsoft.AspNetCore.Server.Kestrel.Core.Internal.Http.Frame.Microsoft.AspNetCore.Http.Features.IHttpResponseFeature.set_StatusCode(Int32 value)
   at Hangfire.Dashboard.AspNetCoreDashboardMiddleware.<Invoke>d__5.MoveNext()
--- End of stack trace from previous location where exception was thrown ---
   at System.Runtime.ExceptionServices.ExceptionDispatchInfo.Throw()
   at System.Runtime.CompilerServices.TaskAwaiter.HandleNonSuccessAndDebuggerNotification(Task task)
   at Microsoft.AspNetCore.Builder.Extensions.MapMiddleware.<Invoke>d__3.MoveNext()
--- End of stack trace from previous location where exception was thrown ---
   at System.Runtime.ExceptionServices.ExceptionDispatchInfo.Throw()
   at System.Runtime.CompilerServices.TaskAwaiter.HandleNonSuccessAndDebuggerNotification(Task task)
   at Microsoft.AspNetCore.Hosting.Internal.RequestServicesContainerMiddleware.<Invoke>d__3.MoveNext()
--- End of stack trace from previous location where exception was thrown ---
   at System.Runtime.ExceptionServices.ExceptionDispatchInfo.Throw()
   at System.Runtime.CompilerServices.TaskAwaiter.HandleNonSuccessAndDebuggerNotification(Task task)
   at Microsoft.AspNetCore.Server.Kestrel.Core.Internal.Http.Frame`1.<ProcessRequestsAsync>d__2.MoveNext()
2019-12-31 18:01:54,908 [6] ERROR Microsoft.AspNetCore.Server.Kestrel - Connection id "0HLSDR0IA22Q8", Request id "0HLSDR0IA22Q8:00000003": An unhandled exception was thrown by the application.
System.InvalidOperationException: StatusCode cannot be set because the response has already started.
   at Microsoft.AspNetCore.Server.Kestrel.Core.Internal.Http.Frame.ThrowResponseAlreadyStartedException(String value)
   at Microsoft.AspNetCore.Server.Kestrel.Core.Internal.Http.Frame.set_StatusCode(Int32 value)
   at Microsoft.AspNetCore.Server.Kestrel.Core.Internal.Http.Frame.Microsoft.AspNetCore.Http.Features.IHttpResponseFeature.set_StatusCode(Int32 value)
   at Hangfire.Dashboard.AspNetCoreDashboardMiddleware.<Invoke>d__5.MoveNext()
--- End of stack trace from previous location where exception was thrown ---
   at System.Runtime.ExceptionServices.ExceptionDispatchInfo.Throw()
   at System.Runtime.CompilerServices.TaskAwaiter.HandleNonSuccessAndDebuggerNotification(Task task)
   at Microsoft.AspNetCore.Builder.Extensions.MapMiddleware.<Invoke>d__3.MoveNext()
--- End of stack trace from previous location where exception was thrown ---
   at System.Runtime.ExceptionServices.ExceptionDispatchInfo.Throw()
   at System.Runtime.CompilerServices.TaskAwaiter.HandleNonSuccessAndDebuggerNotification(Task task)
   at Microsoft.AspNetCore.Hosting.Internal.RequestServicesContainerMiddleware.<Invoke>d__3.MoveNext()
--- End of stack trace from previous location where exception was thrown ---
   at System.Runtime.ExceptionServices.ExceptionDispatchInfo.Throw()
   at System.Runtime.CompilerServices.TaskAwaiter.HandleNonSuccessAndDebuggerNotification(Task task)
   at Microsoft.AspNetCore.Server.Kestrel.Core.Internal.Http.Frame`1.<ProcessRequestsAsync>d__2.MoveNext()
2019-12-31 18:32:36,361 [44] ERROR Microsoft.AspNetCore.Server.Kestrel - Connection id "0HLSDRIVV69GQ", Request id "0HLSDRIVV69GQ:00000002": An unhandled exception was thrown by the application.
System.NotSupportedException: Ambiguous HTTP method for action - Frame.Application.TestAppService.ContainPermission (Frame.Application). Actions require an explicit HttpMethod binding for Swagger 2.0
   at Swashbuckle.AspNetCore.SwaggerGen.SwaggerGenerator.CreatePathItem(IEnumerable`1 apiDescriptions, ISchemaRegistry schemaRegistry)
   at System.Linq.Enumerable.ToDictionary[TSource,TKey,TElement](IEnumerable`1 source, Func`2 keySelector, Func`2 elementSelector, IEqualityComparer`1 comparer)
   at Swashbuckle.AspNetCore.SwaggerGen.SwaggerGenerator.CreatePathItems(IEnumerable`1 apiDescriptions, ISchemaRegistry schemaRegistry)
   at Swashbuckle.AspNetCore.SwaggerGen.SwaggerGenerator.GetSwagger(String documentName, String host, String basePath, String[] schemes)
   at Swashbuckle.AspNetCore.Swagger.SwaggerMiddleware.<Invoke>d__6.MoveNext()
--- End of stack trace from previous location where exception was thrown ---
   at System.Runtime.ExceptionServices.ExceptionDispatchInfo.Throw()
   at System.Runtime.CompilerServices.TaskAwaiter.HandleNonSuccessAndDebuggerNotification(Task task)
   at Abp.AspNetCore.Security.AbpSecurityHeadersMiddleware.<Invoke>d__2.MoveNext() in C:\work\Test\FrameDemo\ABP\Abp.AspNetCore\AspNetCore\Security\AbpSecurityHeadersMiddleware.cs:line 26
--- End of stack trace from previous location where exception was thrown ---
   at System.Runtime.ExceptionServices.ExceptionDispatchInfo.Throw()
   at System.Runtime.CompilerServices.TaskAwaiter.HandleNonSuccessAndDebuggerNotification(Task task)
   at Microsoft.AspNetCore.Localization.RequestLocalizationMiddleware.<Invoke>d__5.MoveNext()
--- End of stack trace from previous location where exception was thrown ---
   at System.Runtime.ExceptionServices.ExceptionDispatchInfo.Throw()
   at System.Runtime.CompilerServices.TaskAwaiter.HandleNonSuccessAndDebuggerNotification(Task task)
   at Microsoft.AspNetCore.Builder.Extensions.MapMiddleware.<Invoke>d__3.MoveNext()
--- End of stack trace from previous location where exception was thrown ---
   at System.Runtime.ExceptionServices.ExceptionDispatchInfo.Throw()
   at System.Runtime.CompilerServices.TaskAwaiter.HandleNonSuccessAndDebuggerNotification(Task task)
   at Microsoft.AspNetCore.Hosting.Internal.RequestServicesContainerMiddleware.<Invoke>d__3.MoveNext()
--- End of stack trace from previous location where exception was thrown ---
   at System.Runtime.ExceptionServices.ExceptionDispatchInfo.Throw()
   at System.Runtime.CompilerServices.TaskAwaiter.HandleNonSuccessAndDebuggerNotification(Task task)
   at Microsoft.AspNetCore.Server.Kestrel.Core.Internal.Http.Frame`1.<ProcessRequestsAsync>d__2.MoveNext()
2019-12-31 18:34:44,770 [45] ERROR Microsoft.AspNetCore.Server.Kestrel - Connection id "0HLSDRJPPJG7R", Request id "0HLSDRJPPJG7R:00000003": An unhandled exception was thrown by the application.
System.InvalidOperationException: StatusCode cannot be set because the response has already started.
   at Microsoft.AspNetCore.Server.Kestrel.Core.Internal.Http.Frame.ThrowResponseAlreadyStartedException(String value)
   at Microsoft.AspNetCore.Server.Kestrel.Core.Internal.Http.Frame.set_StatusCode(Int32 value)
   at Microsoft.AspNetCore.Server.Kestrel.Core.Internal.Http.Frame.Microsoft.AspNetCore.Http.Features.IHttpResponseFeature.set_StatusCode(Int32 value)
   at Hangfire.Dashboard.AspNetCoreDashboardMiddleware.<Invoke>d__5.MoveNext()
--- End of stack trace from previous location where exception was thrown ---
   at System.Runtime.ExceptionServices.ExceptionDispatchInfo.Throw()
   at System.Runtime.CompilerServices.TaskAwaiter.HandleNonSuccessAndDebuggerNotification(Task task)
   at Microsoft.AspNetCore.Builder.Extensions.MapMiddleware.<Invoke>d__3.MoveNext()
--- End of stack trace from previous location where exception was thrown ---
   at System.Runtime.ExceptionServices.ExceptionDispatchInfo.Throw()
   at System.Runtime.CompilerServices.TaskAwaiter.HandleNonSuccessAndDebuggerNotification(Task task)
   at Microsoft.AspNetCore.Hosting.Internal.RequestServicesContainerMiddleware.<Invoke>d__3.MoveNext()
--- End of stack trace from previous location where exception was thrown ---
   at System.Runtime.ExceptionServices.ExceptionDispatchInfo.Throw()
   at System.Runtime.CompilerServices.TaskAwaiter.HandleNonSuccessAndDebuggerNotification(Task task)
   at Microsoft.AspNetCore.Server.Kestrel.Core.Internal.Http.Frame`1.<ProcessRequestsAsync>d__2.MoveNext()
2019-12-31 18:35:43,436 [5] ERROR Microsoft.AspNetCore.Server.Kestrel - Connection id "0HLSDRJPPJG7T", Request id "0HLSDRJPPJG7T:00000001": An unhandled exception was thrown by the application.
System.AggregateException: One or more errors occurred. (Cannot access a disposed object. A common cause of this error is disposing a context that was resolved from dependency injection and then later trying to use the same context instance elsewhere in your application. This may occur if you are calling Dispose() on the context, or wrapping the context in a using statement. If you are using dependency injection, you should let the dependency injection container take care of disposing context instances.
Object name: 'NapManageDbContext'.) ---> System.ObjectDisposedException: Cannot access a disposed object. A common cause of this error is disposing a context that was resolved from dependency injection and then later trying to use the same context instance elsewhere in your application. This may occur if you are calling Dispose() on the context, or wrapping the context in a using statement. If you are using dependency injection, you should let the dependency injection container take care of disposing context instances.
Object name: 'NapManageDbContext'.
   at Microsoft.EntityFrameworkCore.DbContext.CheckDisposed()
   at Microsoft.EntityFrameworkCore.DbContext.get_DbContextDependencies()
   at Microsoft.EntityFrameworkCore.DbContext.get_Model()
   at Microsoft.EntityFrameworkCore.Internal.InternalDbSet`1.get_EntityType()
   at Microsoft.EntityFrameworkCore.Internal.InternalDbSet`1.get_EntityQueryable()
   at Microsoft.EntityFrameworkCore.Internal.InternalDbSet`1.System.Linq.IQueryable.get_Provider()
   at System.Linq.Queryable.Where[TSource](IQueryable`1 source, Expression`1 predicate)
   at Frame.Application.TestAppService.<ContainPermission>d__10.MoveNext() in C:\work\Test\FrameDemo\Frame.Application\Test\TestAppService.cs:line 90
--- End of stack trace from previous location where exception was thrown ---
   at System.Runtime.ExceptionServices.ExceptionDispatchInfo.Throw()
   at System.Runtime.CompilerServices.TaskAwaiter.HandleNonSuccessAndDebuggerNotification(Task task)
   at System.Runtime.CompilerServices.TaskAwaiter`1.GetResult()
   at Frame.Mvc.MyHangfireAuthorizationFilter.<CheckPermission>d__2.MoveNext() in C:\work\Test\FrameDemo\Frame.Mvc\HangfireAuthorization\MyHangfireAuthorizationFilter.cs:line 69
--- End of stack trace from previous location where exception was thrown ---
   at System.Runtime.ExceptionServices.ExceptionDispatchInfo.Throw()
   at System.Runtime.CompilerServices.TaskAwaiter.HandleNonSuccessAndDebuggerNotification(Task task)
   at System.Runtime.CompilerServices.TaskAwaiter`1.GetResult()
   at Frame.Mvc.MyHangfireAuthorizationFilter.<Verification>d__1.MoveNext() in C:\work\Test\FrameDemo\Frame.Mvc\HangfireAuthorization\MyHangfireAuthorizationFilter.cs:line 61
   --- End of inner exception stack trace ---
   at System.Threading.Tasks.Task.ThrowIfExceptional(Boolean includeTaskCanceledExceptions)
   at System.Threading.Tasks.Task`1.GetResultCore(Boolean waitCompletionNotification)
   at Frame.Mvc.MyHangfireAuthorizationFilter.Authorize(DashboardContext context) in C:\work\Test\FrameDemo\Frame.Mvc\HangfireAuthorization\MyHangfireAuthorizationFilter.cs:line 36
   at Hangfire.Dashboard.AspNetCoreDashboardMiddleware.<Invoke>d__5.MoveNext()
--- End of stack trace from previous location where exception was thrown ---
   at System.Runtime.ExceptionServices.ExceptionDispatchInfo.Throw()
   at System.Runtime.CompilerServices.TaskAwaiter.HandleNonSuccessAndDebuggerNotification(Task task)
   at Microsoft.AspNetCore.Builder.Extensions.MapMiddleware.<Invoke>d__3.MoveNext()
--- End of stack trace from previous location where exception was thrown ---
   at System.Runtime.ExceptionServices.ExceptionDispatchInfo.Throw()
   at System.Runtime.CompilerServices.TaskAwaiter.HandleNonSuccessAndDebuggerNotification(Task task)
   at Microsoft.AspNetCore.Hosting.Internal.RequestServicesContainerMiddleware.<Invoke>d__3.MoveNext()
--- End of stack trace from previous location where exception was thrown ---
   at System.Runtime.ExceptionServices.ExceptionDispatchInfo.Throw()
   at System.Runtime.CompilerServices.TaskAwaiter.HandleNonSuccessAndDebuggerNotification(Task task)
   at Microsoft.AspNetCore.Server.Kestrel.Core.Internal.Http.Frame`1.<ProcessRequestsAsync>d__2.MoveNext()
---> (Inner Exception #0) System.ObjectDisposedException: Cannot access a disposed object. A common cause of this error is disposing a context that was resolved from dependency injection and then later trying to use the same context instance elsewhere in your application. This may occur if you are calling Dispose() on the context, or wrapping the context in a using statement. If you are using dependency injection, you should let the dependency injection container take care of disposing context instances.
Object name: 'NapManageDbContext'.
   at Microsoft.EntityFrameworkCore.DbContext.CheckDisposed()
   at Microsoft.EntityFrameworkCore.DbContext.get_DbContextDependencies()
   at Microsoft.EntityFrameworkCore.DbContext.get_Model()
   at Microsoft.EntityFrameworkCore.Internal.InternalDbSet`1.get_EntityType()
   at Microsoft.EntityFrameworkCore.Internal.InternalDbSet`1.get_EntityQueryable()
   at Microsoft.EntityFrameworkCore.Internal.InternalDbSet`1.System.Linq.IQueryable.get_Provider()
   at System.Linq.Queryable.Where[TSource](IQueryable`1 source, Expression`1 predicate)
   at Frame.Application.TestAppService.<ContainPermission>d__10.MoveNext() in C:\work\Test\FrameDemo\Frame.Application\Test\TestAppService.cs:line 90
--- End of stack trace from previous location where exception was thrown ---
   at System.Runtime.ExceptionServices.ExceptionDispatchInfo.Throw()
   at System.Runtime.CompilerServices.TaskAwaiter.HandleNonSuccessAndDebuggerNotification(Task task)
   at System.Runtime.CompilerServices.TaskAwaiter`1.GetResult()
   at Frame.Mvc.MyHangfireAuthorizationFilter.<CheckPermission>d__2.MoveNext() in C:\work\Test\FrameDemo\Frame.Mvc\HangfireAuthorization\MyHangfireAuthorizationFilter.cs:line 69
--- End of stack trace from previous location where exception was thrown ---
   at System.Runtime.ExceptionServices.ExceptionDispatchInfo.Throw()
   at System.Runtime.CompilerServices.TaskAwaiter.HandleNonSuccessAndDebuggerNotification(Task task)
   at System.Runtime.CompilerServices.TaskAwaiter`1.GetResult()
   at Frame.Mvc.MyHangfireAuthorizationFilter.<Verification>d__1.MoveNext() in C:\work\Test\FrameDemo\Frame.Mvc\HangfireAuthorization\MyHangfireAuthorizationFilter.cs:line 61<---

2019-12-31 18:50:58,113 [6] ERROR Microsoft.AspNetCore.Server.Kestrel - Connection id "0HLSDRSJQNSTE", Request id "0HLSDRSJQNSTE:00000003": An unhandled exception was thrown by the application.
System.AggregateException: One or more errors occurred. (Cannot access a disposed object. A common cause of this error is disposing a context that was resolved from dependency injection and then later trying to use the same context instance elsewhere in your application. This may occur if you are calling Dispose() on the context, or wrapping the context in a using statement. If you are using dependency injection, you should let the dependency injection container take care of disposing context instances.
Object name: 'NapManageDbContext'.) ---> System.ObjectDisposedException: Cannot access a disposed object. A common cause of this error is disposing a context that was resolved from dependency injection and then later trying to use the same context instance elsewhere in your application. This may occur if you are calling Dispose() on the context, or wrapping the context in a using statement. If you are using dependency injection, you should let the dependency injection container take care of disposing context instances.
Object name: 'NapManageDbContext'.
   at Microsoft.EntityFrameworkCore.DbContext.CheckDisposed()
   at Microsoft.EntityFrameworkCore.DbContext.get_DbContextDependencies()
   at Microsoft.EntityFrameworkCore.DbContext.get_Model()
   at Microsoft.EntityFrameworkCore.Internal.InternalDbSet`1.get_EntityType()
   at Microsoft.EntityFrameworkCore.Internal.InternalDbSet`1.get_EntityQueryable()
   at Microsoft.EntityFrameworkCore.Internal.InternalDbSet`1.System.Linq.IQueryable.get_Provider()
   at System.Linq.Queryable.Where[TSource](IQueryable`1 source, Expression`1 predicate)
   at Frame.Application.TestAppService.<ContainPermission>d__10.MoveNext()
--- End of stack trace from previous location where exception was thrown ---
   at System.Runtime.ExceptionServices.ExceptionDispatchInfo.Throw()
   at System.Runtime.CompilerServices.TaskAwaiter.HandleNonSuccessAndDebuggerNotification(Task task)
   at System.Runtime.CompilerServices.TaskAwaiter`1.GetResult()
   at Frame.Mvc.MyHangfireAuthorizationFilter.<CheckPermission>d__3.MoveNext()
--- End of stack trace from previous location where exception was thrown ---
   at System.Runtime.ExceptionServices.ExceptionDispatchInfo.Throw()
   at System.Runtime.CompilerServices.TaskAwaiter.HandleNonSuccessAndDebuggerNotification(Task task)
   at System.Runtime.CompilerServices.TaskAwaiter`1.GetResult()
   at Frame.Mvc.MyHangfireAuthorizationFilter.<Verification>d__2.MoveNext()
   --- End of inner exception stack trace ---
   at System.Threading.Tasks.Task.ThrowIfExceptional(Boolean includeTaskCanceledExceptions)
   at System.Threading.Tasks.Task`1.GetResultCore(Boolean waitCompletionNotification)
   at Frame.Mvc.MyHangfireAuthorizationFilter.Authorize(DashboardContext context)
   at Hangfire.Dashboard.AspNetCoreDashboardMiddleware.<Invoke>d__5.MoveNext()
--- End of stack trace from previous location where exception was thrown ---
   at System.Runtime.ExceptionServices.ExceptionDispatchInfo.Throw()
   at System.Runtime.CompilerServices.TaskAwaiter.HandleNonSuccessAndDebuggerNotification(Task task)
   at Microsoft.AspNetCore.Builder.Extensions.MapMiddleware.<Invoke>d__3.MoveNext()
--- End of stack trace from previous location where exception was thrown ---
   at System.Runtime.ExceptionServices.ExceptionDispatchInfo.Throw()
   at System.Runtime.CompilerServices.TaskAwaiter.HandleNonSuccessAndDebuggerNotification(Task task)
   at Microsoft.AspNetCore.Hosting.Internal.RequestServicesContainerMiddleware.<Invoke>d__3.MoveNext()
--- End of stack trace from previous location where exception was thrown ---
   at System.Runtime.ExceptionServices.ExceptionDispatchInfo.Throw()
   at System.Runtime.CompilerServices.TaskAwaiter.HandleNonSuccessAndDebuggerNotification(Task task)
   at Microsoft.AspNetCore.Server.Kestrel.Core.Internal.Http.Frame`1.<ProcessRequestsAsync>d__2.MoveNext()
---> (Inner Exception #0) System.ObjectDisposedException: Cannot access a disposed object. A common cause of this error is disposing a context that was resolved from dependency injection and then later trying to use the same context instance elsewhere in your application. This may occur if you are calling Dispose() on the context, or wrapping the context in a using statement. If you are using dependency injection, you should let the dependency injection container take care of disposing context instances.
Object name: 'NapManageDbContext'.
   at Microsoft.EntityFrameworkCore.DbContext.CheckDisposed()
   at Microsoft.EntityFrameworkCore.DbContext.get_DbContextDependencies()
   at Microsoft.EntityFrameworkCore.DbContext.get_Model()
   at Microsoft.EntityFrameworkCore.Internal.InternalDbSet`1.get_EntityType()
   at Microsoft.EntityFrameworkCore.Internal.InternalDbSet`1.get_EntityQueryable()
   at Microsoft.EntityFrameworkCore.Internal.InternalDbSet`1.System.Linq.IQueryable.get_Provider()
   at System.Linq.Queryable.Where[TSource](IQueryable`1 source, Expression`1 predicate)
   at Frame.Application.TestAppService.<ContainPermission>d__10.MoveNext()
--- End of stack trace from previous location where exception was thrown ---
   at System.Runtime.ExceptionServices.ExceptionDispatchInfo.Throw()
   at System.Runtime.CompilerServices.TaskAwaiter.HandleNonSuccessAndDebuggerNotification(Task task)
   at System.Runtime.CompilerServices.TaskAwaiter`1.GetResult()
   at Frame.Mvc.MyHangfireAuthorizationFilter.<CheckPermission>d__3.MoveNext()
--- End of stack trace from previous location where exception was thrown ---
   at System.Runtime.ExceptionServices.ExceptionDispatchInfo.Throw()
   at System.Runtime.CompilerServices.TaskAwaiter.HandleNonSuccessAndDebuggerNotification(Task task)
   at System.Runtime.CompilerServices.TaskAwaiter`1.GetResult()
   at Frame.Mvc.MyHangfireAuthorizationFilter.<Verification>d__2.MoveNext()<---

2019-12-31 18:51:55,767 [44] ERROR Microsoft.AspNetCore.Server.Kestrel - Connection id "0HLSDRTJ6T7M8", Request id "0HLSDRTJ6T7M8:00000003": An unhandled exception was thrown by the application.
System.AggregateException: One or more errors occurred. (Cannot access a disposed object. A common cause of this error is disposing a context that was resolved from dependency injection and then later trying to use the same context instance elsewhere in your application. This may occur if you are calling Dispose() on the context, or wrapping the context in a using statement. If you are using dependency injection, you should let the dependency injection container take care of disposing context instances.
Object name: 'NapManageDbContext'.) ---> System.ObjectDisposedException: Cannot access a disposed object. A common cause of this error is disposing a context that was resolved from dependency injection and then later trying to use the same context instance elsewhere in your application. This may occur if you are calling Dispose() on the context, or wrapping the context in a using statement. If you are using dependency injection, you should let the dependency injection container take care of disposing context instances.
Object name: 'NapManageDbContext'.
   at Microsoft.EntityFrameworkCore.DbContext.CheckDisposed()
   at Microsoft.EntityFrameworkCore.DbContext.get_DbContextDependencies()
   at Microsoft.EntityFrameworkCore.DbContext.get_Model()
   at Microsoft.EntityFrameworkCore.Internal.InternalDbSet`1.get_EntityType()
   at Microsoft.EntityFrameworkCore.Internal.InternalDbSet`1.get_EntityQueryable()
   at Microsoft.EntityFrameworkCore.Internal.InternalDbSet`1.System.Linq.IQueryable.get_Provider()
   at System.Linq.Queryable.Where[TSource](IQueryable`1 source, Expression`1 predicate)
   at Frame.Application.TestAppService.<ContainPermission>d__10.MoveNext() in C:\work\Test\FrameDemo\Frame.Application\Test\TestAppService.cs:line 90
--- End of stack trace from previous location where exception was thrown ---
   at System.Runtime.ExceptionServices.ExceptionDispatchInfo.Throw()
   at System.Runtime.CompilerServices.TaskAwaiter.HandleNonSuccessAndDebuggerNotification(Task task)
   at System.Runtime.CompilerServices.TaskAwaiter`1.GetResult()
   at Frame.Mvc.MyHangfireAuthorizationFilter.<CheckPermission>d__3.MoveNext() in C:\work\Test\FrameDemo\Frame.Mvc\HangfireAuthorization\MyHangfireAuthorizationFilter.cs:line 74
--- End of stack trace from previous location where exception was thrown ---
   at System.Runtime.ExceptionServices.ExceptionDispatchInfo.Throw()
   at System.Runtime.CompilerServices.TaskAwaiter.HandleNonSuccessAndDebuggerNotification(Task task)
   at System.Runtime.CompilerServices.TaskAwaiter`1.GetResult()
   at Frame.Mvc.MyHangfireAuthorizationFilter.<Verification>d__2.MoveNext() in C:\work\Test\FrameDemo\Frame.Mvc\HangfireAuthorization\MyHangfireAuthorizationFilter.cs:line 66
   --- End of inner exception stack trace ---
   at System.Threading.Tasks.Task.ThrowIfExceptional(Boolean includeTaskCanceledExceptions)
   at System.Threading.Tasks.Task`1.GetResultCore(Boolean waitCompletionNotification)
   at Frame.Mvc.MyHangfireAuthorizationFilter.Authorize(DashboardContext context) in C:\work\Test\FrameDemo\Frame.Mvc\HangfireAuthorization\MyHangfireAuthorizationFilter.cs:line 41
   at Hangfire.Dashboard.AspNetCoreDashboardMiddleware.<Invoke>d__5.MoveNext()
--- End of stack trace from previous location where exception was thrown ---
   at System.Runtime.ExceptionServices.ExceptionDispatchInfo.Throw()
   at System.Runtime.CompilerServices.TaskAwaiter.HandleNonSuccessAndDebuggerNotification(Task task)
   at Microsoft.AspNetCore.Builder.Extensions.MapMiddleware.<Invoke>d__3.MoveNext()
--- End of stack trace from previous location where exception was thrown ---
   at System.Runtime.ExceptionServices.ExceptionDispatchInfo.Throw()
   at System.Runtime.CompilerServices.TaskAwaiter.HandleNonSuccessAndDebuggerNotification(Task task)
   at Microsoft.AspNetCore.Hosting.Internal.RequestServicesContainerMiddleware.<Invoke>d__3.MoveNext()
--- End of stack trace from previous location where exception was thrown ---
   at System.Runtime.ExceptionServices.ExceptionDispatchInfo.Throw()
   at System.Runtime.CompilerServices.TaskAwaiter.HandleNonSuccessAndDebuggerNotification(Task task)
   at Microsoft.AspNetCore.Server.Kestrel.Core.Internal.Http.Frame`1.<ProcessRequestsAsync>d__2.MoveNext()
---> (Inner Exception #0) System.ObjectDisposedException: Cannot access a disposed object. A common cause of this error is disposing a context that was resolved from dependency injection and then later trying to use the same context instance elsewhere in your application. This may occur if you are calling Dispose() on the context, or wrapping the context in a using statement. If you are using dependency injection, you should let the dependency injection container take care of disposing context instances.
Object name: 'NapManageDbContext'.
   at Microsoft.EntityFrameworkCore.DbContext.CheckDisposed()
   at Microsoft.EntityFrameworkCore.DbContext.get_DbContextDependencies()
   at Microsoft.EntityFrameworkCore.DbContext.get_Model()
   at Microsoft.EntityFrameworkCore.Internal.InternalDbSet`1.get_EntityType()
   at Microsoft.EntityFrameworkCore.Internal.InternalDbSet`1.get_EntityQueryable()
   at Microsoft.EntityFrameworkCore.Internal.InternalDbSet`1.System.Linq.IQueryable.get_Provider()
   at System.Linq.Queryable.Where[TSource](IQueryable`1 source, Expression`1 predicate)
   at Frame.Application.TestAppService.<ContainPermission>d__10.MoveNext() in C:\work\Test\FrameDemo\Frame.Application\Test\TestAppService.cs:line 90
--- End of stack trace from previous location where exception was thrown ---
   at System.Runtime.ExceptionServices.ExceptionDispatchInfo.Throw()
   at System.Runtime.CompilerServices.TaskAwaiter.HandleNonSuccessAndDebuggerNotification(Task task)
   at System.Runtime.CompilerServices.TaskAwaiter`1.GetResult()
   at Frame.Mvc.MyHangfireAuthorizationFilter.<CheckPermission>d__3.MoveNext() in C:\work\Test\FrameDemo\Frame.Mvc\HangfireAuthorization\MyHangfireAuthorizationFilter.cs:line 74
--- End of stack trace from previous location where exception was thrown ---
   at System.Runtime.ExceptionServices.ExceptionDispatchInfo.Throw()
   at System.Runtime.CompilerServices.TaskAwaiter.HandleNonSuccessAndDebuggerNotification(Task task)
   at System.Runtime.CompilerServices.TaskAwaiter`1.GetResult()
   at Frame.Mvc.MyHangfireAuthorizationFilter.<Verification>d__2.MoveNext() in C:\work\Test\FrameDemo\Frame.Mvc\HangfireAuthorization\MyHangfireAuthorizationFilter.cs:line 66<---

2019-12-31 18:52:08,337 [5] ERROR Microsoft.AspNetCore.Server.Kestrel - Connection id "0HLSDRTJ6T7M8", Request id "0HLSDRTJ6T7M8:00000004": An unhandled exception was thrown by the application.
System.AggregateException: One or more errors occurred. (Cannot access a disposed object. A common cause of this error is disposing a context that was resolved from dependency injection and then later trying to use the same context instance elsewhere in your application. This may occur if you are calling Dispose() on the context, or wrapping the context in a using statement. If you are using dependency injection, you should let the dependency injection container take care of disposing context instances.
Object name: 'NapManageDbContext'.) ---> System.ObjectDisposedException: Cannot access a disposed object. A common cause of this error is disposing a context that was resolved from dependency injection and then later trying to use the same context instance elsewhere in your application. This may occur if you are calling Dispose() on the context, or wrapping the context in a using statement. If you are using dependency injection, you should let the dependency injection container take care of disposing context instances.
Object name: 'NapManageDbContext'.
   at Microsoft.EntityFrameworkCore.DbContext.CheckDisposed()
   at Microsoft.EntityFrameworkCore.DbContext.get_DbContextDependencies()
   at Microsoft.EntityFrameworkCore.DbContext.get_Model()
   at Microsoft.EntityFrameworkCore.Internal.InternalDbSet`1.get_EntityType()
   at Microsoft.EntityFrameworkCore.Internal.InternalDbSet`1.get_EntityQueryable()
   at Microsoft.EntityFrameworkCore.Internal.InternalDbSet`1.System.Linq.IQueryable.get_Provider()
   at System.Linq.Queryable.Where[TSource](IQueryable`1 source, Expression`1 predicate)
   at Frame.Application.TestAppService.<ContainPermission>d__10.MoveNext() in C:\work\Test\FrameDemo\Frame.Application\Test\TestAppService.cs:line 90
--- End of stack trace from previous location where exception was thrown ---
   at System.Runtime.ExceptionServices.ExceptionDispatchInfo.Throw()
   at System.Runtime.CompilerServices.TaskAwaiter.HandleNonSuccessAndDebuggerNotification(Task task)
   at System.Runtime.CompilerServices.TaskAwaiter`1.GetResult()
   at Frame.Mvc.MyHangfireAuthorizationFilter.<CheckPermission>d__3.MoveNext() in C:\work\Test\FrameDemo\Frame.Mvc\HangfireAuthorization\MyHangfireAuthorizationFilter.cs:line 74
--- End of stack trace from previous location where exception was thrown ---
   at System.Runtime.ExceptionServices.ExceptionDispatchInfo.Throw()
   at System.Runtime.CompilerServices.TaskAwaiter.HandleNonSuccessAndDebuggerNotification(Task task)
   at System.Runtime.CompilerServices.TaskAwaiter`1.GetResult()
   at Frame.Mvc.MyHangfireAuthorizationFilter.<Verification>d__2.MoveNext() in C:\work\Test\FrameDemo\Frame.Mvc\HangfireAuthorization\MyHangfireAuthorizationFilter.cs:line 66
   --- End of inner exception stack trace ---
   at System.Threading.Tasks.Task.ThrowIfExceptional(Boolean includeTaskCanceledExceptions)
   at System.Threading.Tasks.Task`1.GetResultCore(Boolean waitCompletionNotification)
   at Frame.Mvc.MyHangfireAuthorizationFilter.Authorize(DashboardContext context) in C:\work\Test\FrameDemo\Frame.Mvc\HangfireAuthorization\MyHangfireAuthorizationFilter.cs:line 41
   at Hangfire.Dashboard.AspNetCoreDashboardMiddleware.<Invoke>d__5.MoveNext()
--- End of stack trace from previous location where exception was thrown ---
   at System.Runtime.ExceptionServices.ExceptionDispatchInfo.Throw()
   at System.Runtime.CompilerServices.TaskAwaiter.HandleNonSuccessAndDebuggerNotification(Task task)
   at Microsoft.AspNetCore.Builder.Extensions.MapMiddleware.<Invoke>d__3.MoveNext()
--- End of stack trace from previous location where exception was thrown ---
   at System.Runtime.ExceptionServices.ExceptionDispatchInfo.Throw()
   at System.Runtime.CompilerServices.TaskAwaiter.HandleNonSuccessAndDebuggerNotification(Task task)
   at Microsoft.AspNetCore.Hosting.Internal.RequestServicesContainerMiddleware.<Invoke>d__3.MoveNext()
--- End of stack trace from previous location where exception was thrown ---
   at System.Runtime.ExceptionServices.ExceptionDispatchInfo.Throw()
   at System.Runtime.CompilerServices.TaskAwaiter.HandleNonSuccessAndDebuggerNotification(Task task)
   at Microsoft.AspNetCore.Server.Kestrel.Core.Internal.Http.Frame`1.<ProcessRequestsAsync>d__2.MoveNext()
---> (Inner Exception #0) System.ObjectDisposedException: Cannot access a disposed object. A common cause of this error is disposing a context that was resolved from dependency injection and then later trying to use the same context instance elsewhere in your application. This may occur if you are calling Dispose() on the context, or wrapping the context in a using statement. If you are using dependency injection, you should let the dependency injection container take care of disposing context instances.
Object name: 'NapManageDbContext'.
   at Microsoft.EntityFrameworkCore.DbContext.CheckDisposed()
   at Microsoft.EntityFrameworkCore.DbContext.get_DbContextDependencies()
   at Microsoft.EntityFrameworkCore.DbContext.get_Model()
   at Microsoft.EntityFrameworkCore.Internal.InternalDbSet`1.get_EntityType()
   at Microsoft.EntityFrameworkCore.Internal.InternalDbSet`1.get_EntityQueryable()
   at Microsoft.EntityFrameworkCore.Internal.InternalDbSet`1.System.Linq.IQueryable.get_Provider()
   at System.Linq.Queryable.Where[TSource](IQueryable`1 source, Expression`1 predicate)
   at Frame.Application.TestAppService.<ContainPermission>d__10.MoveNext() in C:\work\Test\FrameDemo\Frame.Application\Test\TestAppService.cs:line 90
--- End of stack trace from previous location where exception was thrown ---
   at System.Runtime.ExceptionServices.ExceptionDispatchInfo.Throw()
   at System.Runtime.CompilerServices.TaskAwaiter.HandleNonSuccessAndDebuggerNotification(Task task)
   at System.Runtime.CompilerServices.TaskAwaiter`1.GetResult()
   at Frame.Mvc.MyHangfireAuthorizationFilter.<CheckPermission>d__3.MoveNext() in C:\work\Test\FrameDemo\Frame.Mvc\HangfireAuthorization\MyHangfireAuthorizationFilter.cs:line 74
--- End of stack trace from previous location where exception was thrown ---
   at System.Runtime.ExceptionServices.ExceptionDispatchInfo.Throw()
   at System.Runtime.CompilerServices.TaskAwaiter.HandleNonSuccessAndDebuggerNotification(Task task)
   at System.Runtime.CompilerServices.TaskAwaiter`1.GetResult()
   at Frame.Mvc.MyHangfireAuthorizationFilter.<Verification>d__2.MoveNext() in C:\work\Test\FrameDemo\Frame.Mvc\HangfireAuthorization\MyHangfireAuthorizationFilter.cs:line 66<---

2019-12-31 18:57:54,844 [45] ERROR Microsoft.AspNetCore.Server.Kestrel - Connection id "0HLSDS0TRR93K", Request id "0HLSDS0TRR93K:00000003": An unhandled exception was thrown by the application.
System.AggregateException: One or more errors occurred. (Cannot access a disposed object. A common cause of this error is disposing a context that was resolved from dependency injection and then later trying to use the same context instance elsewhere in your application. This may occur if you are calling Dispose() on the context, or wrapping the context in a using statement. If you are using dependency injection, you should let the dependency injection container take care of disposing context instances.
Object name: 'NapManageDbContext'.) ---> System.ObjectDisposedException: Cannot access a disposed object. A common cause of this error is disposing a context that was resolved from dependency injection and then later trying to use the same context instance elsewhere in your application. This may occur if you are calling Dispose() on the context, or wrapping the context in a using statement. If you are using dependency injection, you should let the dependency injection container take care of disposing context instances.
Object name: 'NapManageDbContext'.
   at Microsoft.EntityFrameworkCore.DbContext.CheckDisposed()
   at Microsoft.EntityFrameworkCore.DbContext.get_DbContextDependencies()
   at Microsoft.EntityFrameworkCore.DbContext.get_Model()
   at Microsoft.EntityFrameworkCore.Internal.InternalDbSet`1.get_EntityType()
   at Microsoft.EntityFrameworkCore.Internal.InternalDbSet`1.get_EntityQueryable()
   at Microsoft.EntityFrameworkCore.Internal.InternalDbSet`1.System.Linq.IQueryable.get_Provider()
   at System.Linq.Queryable.Where[TSource](IQueryable`1 source, Expression`1 predicate)
   at Frame.Application.TestAppService.<ContainPermission>d__10.MoveNext() in C:\work\Test\FrameDemo\Frame.Application\Test\TestAppService.cs:line 90
--- End of stack trace from previous location where exception was thrown ---
   at System.Runtime.ExceptionServices.ExceptionDispatchInfo.Throw()
   at System.Runtime.CompilerServices.TaskAwaiter.HandleNonSuccessAndDebuggerNotification(Task task)
   at System.Runtime.CompilerServices.TaskAwaiter`1.GetResult()
   at Frame.Mvc.MyHangfireAuthorizationFilter.<CheckPermission>d__3.MoveNext() in C:\work\Test\FrameDemo\Frame.Mvc\HangfireAuthorization\MyHangfireAuthorizationFilter.cs:line 75
--- End of stack trace from previous location where exception was thrown ---
   at System.Runtime.ExceptionServices.ExceptionDispatchInfo.Throw()
   at System.Runtime.CompilerServices.TaskAwaiter.HandleNonSuccessAndDebuggerNotification(Task task)
   at System.Runtime.CompilerServices.TaskAwaiter`1.GetResult()
   at Frame.Mvc.MyHangfireAuthorizationFilter.<Verification>d__2.MoveNext() in C:\work\Test\FrameDemo\Frame.Mvc\HangfireAuthorization\MyHangfireAuthorizationFilter.cs:line 66
   --- End of inner exception stack trace ---
   at System.Threading.Tasks.Task.ThrowIfExceptional(Boolean includeTaskCanceledExceptions)
   at System.Threading.Tasks.Task`1.GetResultCore(Boolean waitCompletionNotification)
   at Frame.Mvc.MyHangfireAuthorizationFilter.Authorize(DashboardContext context) in C:\work\Test\FrameDemo\Frame.Mvc\HangfireAuthorization\MyHangfireAuthorizationFilter.cs:line 41
   at Hangfire.Dashboard.AspNetCoreDashboardMiddleware.<Invoke>d__5.MoveNext()
--- End of stack trace from previous location where exception was thrown ---
   at System.Runtime.ExceptionServices.ExceptionDispatchInfo.Throw()
   at System.Runtime.CompilerServices.TaskAwaiter.HandleNonSuccessAndDebuggerNotification(Task task)
   at Microsoft.AspNetCore.Builder.Extensions.MapMiddleware.<Invoke>d__3.MoveNext()
--- End of stack trace from previous location where exception was thrown ---
   at System.Runtime.ExceptionServices.ExceptionDispatchInfo.Throw()
   at System.Runtime.CompilerServices.TaskAwaiter.HandleNonSuccessAndDebuggerNotification(Task task)
   at Microsoft.AspNetCore.Hosting.Internal.RequestServicesContainerMiddleware.<Invoke>d__3.MoveNext()
--- End of stack trace from previous location where exception was thrown ---
   at System.Runtime.ExceptionServices.ExceptionDispatchInfo.Throw()
   at System.Runtime.CompilerServices.TaskAwaiter.HandleNonSuccessAndDebuggerNotification(Task task)
   at Microsoft.AspNetCore.Server.Kestrel.Core.Internal.Http.Frame`1.<ProcessRequestsAsync>d__2.MoveNext()
---> (Inner Exception #0) System.ObjectDisposedException: Cannot access a disposed object. A common cause of this error is disposing a context that was resolved from dependency injection and then later trying to use the same context instance elsewhere in your application. This may occur if you are calling Dispose() on the context, or wrapping the context in a using statement. If you are using dependency injection, you should let the dependency injection container take care of disposing context instances.
Object name: 'NapManageDbContext'.
   at Microsoft.EntityFrameworkCore.DbContext.CheckDisposed()
   at Microsoft.EntityFrameworkCore.DbContext.get_DbContextDependencies()
   at Microsoft.EntityFrameworkCore.DbContext.get_Model()
   at Microsoft.EntityFrameworkCore.Internal.InternalDbSet`1.get_EntityType()
   at Microsoft.EntityFrameworkCore.Internal.InternalDbSet`1.get_EntityQueryable()
   at Microsoft.EntityFrameworkCore.Internal.InternalDbSet`1.System.Linq.IQueryable.get_Provider()
   at System.Linq.Queryable.Where[TSource](IQueryable`1 source, Expression`1 predicate)
   at Frame.Application.TestAppService.<ContainPermission>d__10.MoveNext() in C:\work\Test\FrameDemo\Frame.Application\Test\TestAppService.cs:line 90
--- End of stack trace from previous location where exception was thrown ---
   at System.Runtime.ExceptionServices.ExceptionDispatchInfo.Throw()
   at System.Runtime.CompilerServices.TaskAwaiter.HandleNonSuccessAndDebuggerNotification(Task task)
   at System.Runtime.CompilerServices.TaskAwaiter`1.GetResult()
   at Frame.Mvc.MyHangfireAuthorizationFilter.<CheckPermission>d__3.MoveNext() in C:\work\Test\FrameDemo\Frame.Mvc\HangfireAuthorization\MyHangfireAuthorizationFilter.cs:line 75
--- End of stack trace from previous location where exception was thrown ---
   at System.Runtime.ExceptionServices.ExceptionDispatchInfo.Throw()
   at System.Runtime.CompilerServices.TaskAwaiter.HandleNonSuccessAndDebuggerNotification(Task task)
   at System.Runtime.CompilerServices.TaskAwaiter`1.GetResult()
   at Frame.Mvc.MyHangfireAuthorizationFilter.<Verification>d__2.MoveNext() in C:\work\Test\FrameDemo\Frame.Mvc\HangfireAuthorization\MyHangfireAuthorizationFilter.cs:line 66<---

